Workbook

Sheet WC26
B1: TỔNG CỘNG | I1: 1 | K1: 2 | M1: 3 | O1: 4 | Q1: 5 | S1: 6 | U1: 7 | W1: 8 | Y1: 9 | AA1: 10 | AC1: 11 | AE1: 12 | AG1: 13 | AI1: 14 | AK1: 15 | AM1: 16 | AO1: 17 | AQ1: 18 | AS1: 19 | AU1: 20 | AW1: 21 | AY1: 22 | BA1: 23 | BC1: 24 | BE1: 25 | BG1: 26 | BI1: 27 | BN1: 1 | BP1: 2 | BR1: 3 | BT1: 4 | BV1: 5 | BX1: 6 | BZ1: 7 | CB1: 8 | CD1: 9 | CF1: 10 | CH1: 11 | CJ1: 12 | CL1: 13 | CN1: 14 | CP1: 15 | CR1: 16 | CT1: 17 | CV1: 18 | CX1: 19 | CZ1: 20 | DB1: 21 | DD1: 22
I2: =BN3 -> 0 | K2: =BP3 -> 110000 | M2: =BR3+M4 -> 5000 | O2: =BT3+O4 -> 135000 | Q2: =BV3+Q4 -> 155000 | S2: =BX3 -> 305000 | U2: =BZ3 -> 160000 | W2: =CB3+W4 -> 160000 | Y2: =CD3 -> 180000 | AA2: =CF3+AA4 -> 10000 | AC2: =CH3+AC4 -> 35000 | AE2: =CJ3+AE4 -> 155000 | AG2: =CL3 -> 10000 | AI2: =CN3 -> 10000 | AK2: =CP3+AK4 -> 160000 | AM2: =CR3 -> 40000 | AO2: =CT3+AO4 -> 580000 | AQ2: =CV3 -> 170000 | AS2: =CX3 -> 610000 | AU2: =CZ3 -> 50000 | AW2: =DB3 -> 15000 | AY2: =DD3 -> 75000 | BA2: =DF3 -> 180000 | BC2: =DH3 -> 670000 | BE2: =DJ3 -> 180000 | BG2: =DL3 -> 5000 | BI2: =DN3 -> 1015000 | BN2: A.Hòa | BP2: A.Đạt | BR2: C. Hương | BT2: A. Hải | BV2: Thanh | BX2: A. Tuyển | BZ2: Hoa KHVT | CB2: Dũng KHVT | CD2: Hiếu | CF2: LM.Chủ | CH2: Thành | CJ2: Cường | CL2: A Sơn | CN2: A.Hiệu | CP2: Long | CR2: A. Tuấn | CT2: Trang KHVT | CV2: Hương KHVT | CX2: HOÀN | CZ2: Hiền TVTK | DB2: A. Quyết | DD2: Trường | DF2: San | DH2: Đức Anh | DJ2: Thắng | DL2: a. Dương | DN2: E Sơn
B3: Ngày giờ thi đấu | E3: Cặp đấu | I3: A.Hòa | K3: A.Đạt | M3: C. Hương | O3: A. Hải | Q3: Thanh | S3: A. Tuyển | U3: Hoa KHVT | W3: Dũng KHVT | Y3: Hiếu | AA3: LM.Chủ | AC3: Thành | AE3: Cường | AG3: A Sơn | AI3: A.Hiệu | AK3: Long | AM3: A. Tuấn | AO3: Trang KHVT | AQ3: Hương KHVT | AS3: HOÀN | AU3: Hiền TVTK | AW3: A. Quyết | AY3: Trường | BA3: San | BC3: Đức Anh | BE3: Thắng | BG3: a. Dương | BI3: E Sơn | BN3: =SUM(BN7:BN116) -> 0 | BP3: =SUM(BP7:BP116) -> 110000 | BR3: =SUM(BR7:BR116) -> 5000 | BT3: =SUM(BT7:BT116) -> 135000 | BV3: =SUM(BV7:BV116) -> 155000 | BX3: =SUM(BX7:BX116) -> 305000 | BZ3: =SUM(BZ7:BZ116) -> 160000 | CB3: =SUM(CB7:CB116) -> 160000 | CD3: =SUM(CD7:CD116) -> 180000 | CF3: =SUM(CF7:CF116) -> 10000 | CH3: =SUM(CH7:CH116) -> 35000 | CJ3: =SUM(CJ7:CJ116) -> 155000 | CL3: =SUM(CL7:CL116) -> 10000 | CN3: =SUM(CN7:CN116) -> 10000 | CP3: =SUM(CP7:CP116) -> 160000 | CR3: =SUM(CR7:CR116) -> 40000 | CT3: =SUM(CT7:CT116) -> 580000 | CV3: =SUM(CV7:CV116) -> 170000 | CX3: =SUM(CX7:CX116) -> 610000 | CZ3: =SUM(CZ7:CZ116) -> 50000 | DB3: =SUM(DB7:DB116) -> 15000 | DD3: =SUM(DD7:DD116) -> 75000 | DF3: =SUM(DF7:DF116) -> 180000 | DH3: =SUM(DH7:DH116) -> 670000 | DJ3: =SUM(DJ7:DJ116) -> 180000 | DL3: =SUM(DL7:DL116) -> 5000 | DN3: =SUM(DN7:DN116) -> 1015000
E5: ĐỘI VÔ ĐỊCH
E6: 2 ĐỘI VÀO CHUNG KẾT
B7: 1 | C7: 46185.083 | D7: 46185.083 | E7: Mexico | F7: 2 | G7: 0 | H7: South Africa | I7: 2 | J7: 0 | K7: 2 | L7: 1 | M7: 2 | N7: 0 | O7: 2 | P7: 0 | Q7: =AE7 -> 2 | R7: =AF7 -> 0 | S7: 2 | T7: 1 | U7: 1 | V7: 0 | W7: 1 | X7: 0 | Y7: 1 | Z7: 2 | AC7: 2 | AD7: 1 | AE7: 2 | AF7: 0 | AK7: 1 | AL7: 0 | AM7: 1 | AN7: 0 | AO7: 2 | AP7: 0 | AQ7: =BE7 -> 2 | AR7: =BF7 -> 0 | AS7: 2 | AT7: 0 | AU7: 2 | AV7: 1 | AW7: 1 | AX7: 0 | AY7: 2 | AZ7: 1 | BA7: 1 | BB7: 0 | BC7: 2 | BD7: 0 | BE7: 2 | BF7: 0 | BG7: 1 | BH7: 0 | BI7: =H.Son!H7 -> 2 | BJ7: =H.Son!I7 -> 0 | BN7: =if($F7=$G7,if(and($F7=$G7,I7<>J7),'Thể lệ'!$E$6,if($F7=I7,0,0.5*'Thể lệ'!$E$6)),if(and($F7=I7,$G7=J7),"0",if(($F7-$G7)*(I7-J7)>0,0.5*'Thể lệ'!$E$6,'Thể lệ'!$E$6))) -> 0 | BP7: =if($F7=$G7,if(and($F7=$G7,K7<>L7),'Thể lệ'!$E$6,if($F7=K7,0,0.5*'Thể lệ'!$E$6)),if(and($F7=K7,$G7=L7),"0",if(($F7-$G7)*(K7-L7)>0,0.5*'Thể lệ'!$E$6,'Thể lệ'!$E$6))) -> 5000 | BR7: =if($F7=$G7,if(and($F7=$G7,M7<>N7),'Thể lệ'!$E$6,if($F7=M7,0,0.5*'Thể lệ'!$E$6)),if(and($F7=M7,$G7=N7),"0",if(($F7-$G7)*(M7-N7)>0,0.5*'Thể lệ'!$E$6,'Thể lệ'!$E$6))) -> 0 | BT7: =if($F7=$G7,if(and($F7=$G7,O7<>P7),'Thể lệ'!$E$6,if($F7=O7,0,0.5*'Thể lệ'!$E$6)),if(and($F7=O7,$G7=P7),"0",if(($F7-$G7)*(O7-P7)>0,0.5*'Thể lệ'!$E$6,'Thể lệ'!$E$6))) -> 0 | BV7: =if($F7=$G7,if(and($F7=$G7,Q7<>R7),'Thể lệ'!$E$6,if($F7=Q7,0,0.5*'Thể lệ'!$E$6)),if(and($F7=Q7,$G7=R7),"0",if(($F7-$G7)*(Q7-R7)>0,0.5*'Thể lệ'!$E$6,'Thể lệ'!$E$6))) -> 0 | BX7: =if($F7=$G7,if(and($F7=$G7,S7<>T7),'Thể lệ'!$E$6,if($F7=S7,0,0.5*'Thể lệ'!$E$6)),if(and($F7=S7,$G7=T7),"0",if(($F7-$G7)*(S7-T7)>0,0.5*'Thể lệ'!$E$6,'Thể lệ'!$E$6))) -> 5000 | BZ7: =if($F7=$G7,if(and($F7=$G7,U7<>V7),'Thể lệ'!$E$6,if($F7=U7,0,0.5*'Thể lệ'!$E$6)),if(and($F7=U7,$G7=V7),"0",if(($F7-$G7)*(U7-V7)>0,0.5*'Thể lệ'!$E$6,'Thể lệ'!$E$6))) -> 5000 | CB7: =if($F7=$G7,if(and($F7=$G7,W7<>X7),'Thể lệ'!$E$6,if($F7=W7,0,0.5*'Thể lệ'!$E$6)),if(and($F7=W7,$G7=X7),"0",if(($F7-$G7)*(W7-X7)>0,0.5*'Thể lệ'!$E$6,'Thể lệ'!$E$6))) -> 5000 | CD7: =if($F7=$G7,if(and($F7=$G7,Y7<>Z7),'Thể lệ'!$E$6,if($F7=Y7,0,0.5*'Thể lệ'!$E$6)),if(and($F7=Y7,$G7=Z7),"0",if(($F7-$G7)*(Y7-Z7)>0,0.5*'Thể lệ'!$E$6,'Thể lệ'!$E$6))) -> 10000 | CF7: =if($F7=$G7,if(and($F7=$G7,AA7<>AB7),'Thể lệ'!$E$6,if($F7=AA7,0,0.5*'Thể lệ'!$E$6)),if(and($F7=AA7,$G7=AB7),"0",if(($F7-$G7)*(AA7-AB7)>0,0.5*'Thể lệ'!$E$6,'Thể lệ'!$E$6))) -> 10000 | CH7: =if($F7=$G7,if(and($F7=$G7,AC7<>AD7),'Thể lệ'!$E$6,if($F7=AC7,0,0.5*'Thể lệ'!$E$6)),if(and($F7=AC7,$G7=AD7),"0",if(($F7-$G7)*(AC7-AD7)>0,0.5*'Thể lệ'!$E$6,'Thể lệ'!$E$6))) -> 5000 | CJ7: =if($F7=$G7,if(and($F7=$G7,AE7<>AF7),'Thể lệ'!$E$6,if($F7=AE7,0,0.5*'Thể lệ'!$E$6)),if(and($F7=AE7,$G7=AF7),"0",if(($F7-$G7)*(AE7-AF7)>0,0.5*'Thể lệ'!$E$6,'Thể lệ'!$E$6))) -> 0 | CL7: =if($F7=$G7,if(and($F7=$G7,AG7<>AH7),'Thể lệ'!$E$6,if($F7=AG7,0,0.5*'Thể lệ'!$E$6)),if(and($F7=AG7,$G7=AH7),"0",if(($F7-$G7)*(AG7-AH7)>0,0.5*'Thể lệ'!$E$6,'Thể lệ'!$E$6))) -> 10000 | CN7: =if($F7=$G7,if(and($F7=$G7,AI7<>AJ7),'Thể lệ'!$E$6,if($F7=AI7,0,0.5*'Thể lệ'!$E$6)),if(and($F7=AI7,$G7=AJ7),"0",if(($F7-$G7)*(AI7-AJ7)>0,0.5*'Thể lệ'!$E$6,'Thể lệ'!$E$6))) -> 10000 | CP7: =if($F7=$G7,if(and($F7=$G7,AK7<>AL7),'Thể lệ'!$E$6,if($F7=AK7,0,0.5*'Thể lệ'!$E$6)),if(and($F7=AK7,$G7=AL7),"0",if(($F7-$G7)*(AK7-AL7)>0,0.5*'Thể lệ'!$E$6,'Thể lệ'!$E$6))) -> 5000 | CR7: =if($F7=$G7,if(and($F7=$G7,AM7<>AN7),'Thể lệ'!$E$6,if($F7=AM7,0,0.5*'Thể lệ'!$E$6)),if(and($F7=AM7,$G7=AN7),"0",if(($F7-$G7)*(AM7-AN7)>0,0.5*'Thể lệ'!$E$6,'Thể lệ'!$E$6))) -> 5000 | CT7: =if($F7=$G7,if(and($F7=$G7,AO7<>AP7),'Thể lệ'!$E$6,if($F7=AO7,0,0.5*'Thể lệ'!$E$6)),if(and($F7=AO7,$G7=AP7),"0",if(($F7-$G7)*(AO7-AP7)>0,0.5*'Thể lệ'!$E$6,'Thể lệ'!$E$6))) -> 0 | CV7: =if($F7=$G7,if(and($F7=$G7,AQ7<>AR7),'Thể lệ'!$E$6,if($F7=AQ7,0,0.5*'Thể lệ'!$E$6)),if(and($F7=AQ7,$G7=AR7),"0",if(($F7-$G7)*(AQ7-AR7)>0,0.5*'Thể lệ'!$E$6,'Thể lệ'!$E$6))) -> 0 | CX7: =if($F7=$G7,if(and($F7=$G7,AS7<>AT7),'Thể lệ'!$E$6,if($F7=AS7,0,0.5*'Thể lệ'!$E$6)),if(and($F7=AS7,$G7=AT7),"0",if(($F7-$G7)*(AS7-AT7)>0,0.5*'Thể lệ'!$E$6,'Thể lệ'!$E$6))) -> 0 | CZ7: =if($F7=$G7,if(and($F7=$G7,AU7<>AV7),'Thể lệ'!$E$6,if($F7=AU7,0,0.5*'Thể lệ'!$E$6)),if(and($F7=AU7,$G7=AV7),"0",if(($F7-$G7)*(AU7-AV7)>0,0.5*'Thể lệ'!$E$6,'Thể lệ'!$E$6))) -> 5000 | DB7: =if($F7=$G7,if(and($F7=$G7,AW7<>AX7),'Thể lệ'!$E$6,if($F7=AW7,0,0.5*'Thể lệ'!$E$6)),if(and($F7=AW7,$G7=AX7),"0",if(($F7-$G7)*(AW7-AX7)>0,0.5*'Thể lệ'!$E$6,'Thể lệ'!$E$6))) -> 5000 | DD7: =if($F7=$G7,if(and($F7=$G7,AY7<>AZ7),'Thể lệ'!$E$6,if($F7=AY7,0,0.5*'Thể lệ'!$E$6)),if(and($F7=AY7,$G7=AZ7),"0",if(($F7-$G7)*(AY7-AZ7)>0,0.5*'Thể lệ'!$E$6,'Thể lệ'!$E$6))) -> 5000 | DF7: =if($F7=$G7,if(and($F7=$G7,BA7<>BB7),'Thể lệ'!$E$6,if($F7=BA7,0,0.5*'Thể lệ'!$E$6)),if(and($F7=BA7,$G7=BB7),"0",if(($F7-$G7)*(BA7-BB7)>0,0.5*'Thể lệ'!$E$6,'Thể lệ'!$E$6))) -> 5000 | DH7: =if($F7=$G7,if(and($F7=$G7,BC7<>BD7),'Thể lệ'!$E$6,if($F7=BC7,0,0.5*'Thể lệ'!$E$6)),if(and($F7=BC7,$G7=BD7),"0",if(($F7-$G7)*(BC7-BD7)>0,0.5*'Thể lệ'!$E$6,'Thể lệ'!$E$6))) -> 0 | DJ7: =if($F7=$G7,if(and($F7=$G7,BE7<>BF7),'Thể lệ'!$E$6,if($F7=BE7,0,0.5*'Thể lệ'!$E$6)),if(and($F7=BE7,$G7=BF7),"0",if(($F7-$G7)*(BE7-BF7)>0,0.5*'Thể lệ'!$E$6,'Thể lệ'!$E$6))) -> 0 | DL7: =if($F7=$G7,if(and($F7=$G7,BG7<>BH7),'Thể lệ'!$E$6,if($F7=BG7,0,0.5*'Thể lệ'!$E$6)),if(and($F7=BG7,$G7=BH7),"0",if(($F7-$G7)*(BG7-BH7)>0,0.5*'Thể lệ'!$E$6,'Thể lệ'!$E$6))) -> 5000 | DN7: =if($F7=$G7,if(and($F7=$G7,BI7<>BJ7),'Thể lệ'!$E$6,if($F7=BI7,0,0.5*'Thể lệ'!$E$6)),if(and($F7=BI7,$G7=BJ7),"0",if(($F7-$G7)*(BI7-BJ7)>0,0.5*'Thể lệ'!$E$6,'Thể lệ'!$E$6))) -> 0
B8: 2 | C8: 46185.375 | D8: 46185.375 | E8: Rep. of Korea | H8: Czech Rep. | K8: 1 | L8: 2 | M8: 1 | N8: 1 | O8: 1 | P8: 1 | Q8: =AE8 -> 1 | R8: 1 | S8: 1 | T8: 1 | U8: 1 | V8: 2 | W8: 1 | X8: 2 | Y8: 2 | Z8: 1 | AC8: 1 | AD8: 2 | AE8: 1 | AF8: 2 | AK8: 1 | AL8: 1 | AM8: 1 | AN8: 2 | AO8: 1 | AP8: 2 | AQ8: =BE8 -> 1 | AR8: =BF8 -> 1 | AS8: 1 | AT8: 1 | AU8: 1 | AV8: 1 | AW8: 2 | AX8: 1 | AY8: 2 | AZ8: 0 | BA8: 1 | BB8: 2 | BC8: 1 | BD8: 0 | BE8: 1 | BF8: 1 | BI8: =H.Son!H8 -> 1 | BJ8: =H.Son!I8 -> 1 | BN8: =if($F8=$G8,if(and($F8=$G8,I8<>J8),'Thể lệ'!$E$6,if($F8=I8,0,0.5*'Thể lệ'!$E$6)),if(and($F8=I8,$G8=J8),"0",if(($F8-$G8)*(I8-J8)>0,0.5*'Thể lệ'!$E$6,'Thể lệ'!$E$6))) -> 0 | BP8: =if($F8=$G8,if(and($F8=$G8,K8<>L8),'Thể lệ'!$E$6,if($F8=K8,0,0.5*'Thể lệ'!$E$6)),if(and($F8=K8,$G8=L8),"0",if(($F8-$G8)*(K8-L8)>0,0.5*'Thể lệ'!$E$6,'Thể lệ'!$E$6))) -> 10000 | BR8: =if($F8=$G8,if(and($F8=$G8,M8<>N8),'Thể lệ'!$E$6,if($F8=M8,0,0.5*'Thể lệ'!$E$6)),if(and($F8=M8,$G8=N8),"0",if(($F8-$G8)*(M8-N8)>0,0.5*'Thể lệ'!$E$6,'Thể lệ'!$E$6))) -> 5000 | BT8: =if($F8=$G8,if(and($F8=$G8,O8<>P8),'Thể lệ'!$E$6,if($F8=O8,0,0.5*'Thể lệ'!$E$6)),if(and($F8=O8,$G8=P8),"0",if(($F8-$G8)*(O8-P8)>0,0.5*'Thể lệ'!$E$6,'Thể lệ'!$E$6))) -> 5000 | BV8: =if($F8=$G8,if(and($F8=$G8,Q8<>R8),'Thể lệ'!$E$6,if($F8=Q8,0,0.5*'Thể lệ'!$E$6)),if(and($F8=Q8,$G8=R8),"0",if(($F8-$G8)*(Q8-R8)>0,0.5*'Thể lệ'!$E$6,'Thể lệ'!$E$6))) -> 5000 | BX8: =if($F8=$G8,if(and($F8=$G8,S8<>T8),'Thể lệ'!$E$6,if($F8=S8,0,0.5*'Thể lệ'!$E$6)),if(and($F8=S8,$G8=T8),"0",if(($F8-$G8)*(S8-T8)>0,0.5*'Thể lệ'!$E$6,'Thể lệ'!$E$6))) -> 5000 | BZ8: =if($F8=$G8,if(and($F8=$G8,U8<>V8),'Thể lệ'!$E$6,if($F8=U8,0,0.5*'Thể lệ'!$E$6)),if(and($F8=U8,$G8=V8),"0",if(($F8-$G8)*(U8-V8)>0,0.5*'Thể lệ'!$E$6,'Thể lệ'!$E$6))) -> 10000 | CB8: =if($F8=$G8,if(and($F8=$G8,W8<>X8),'Thể lệ'!$E$6,if($F8=W8,0,0.5*'Thể lệ'!$E$6)),if(and($F8=W8,$G8=X8),"0",if(($F8-$G8)*(W8-X8)>0,0.5*'Thể lệ'!$E$6,'Thể lệ'!$E$6))) -> 10000 | CD8: =if($F8=$G8,if(and($F8=$G8,Y8<>Z8),'Thể lệ'!$E$6,if($F8=Y8,0,0.5*'Thể lệ'!$E$6)),if(and($F8=Y8,$G8=Z8),"0",if(($F8-$G8)*(Y8-Z8)>0,0.5*'Thể lệ'!$E$6,'Thể lệ'!$E$6))) -> 10000 | CF8: =if($F8=$G8,if(and($F8=$G8,AA8<>AB8),'Thể lệ'!$E$6,if($F8=AA8,0,0.5*'Thể lệ'!$E$6)),if(and($F8=AA8,$G8=AB8),"0",if(($F8-$G8)*(AA8-AB8)>0,0.5*'Thể lệ'!$E$6,'Thể lệ'!$E$6))) -> 0 | CH8: =if($F8=$G8,if(and($F8=$G8,AC8<>AD8),'Thể lệ'!$E$6,if($F8=AC8,0,0.5*'Thể lệ'!$E$6)),if(and($F8=AC8,$G8=AD8),"0",if(($F8-$G8)*(AC8-AD8)>0,0.5*'Thể lệ'!$E$6,'Thể lệ'!$E$6))) -> 10000 | CJ8: =if($F8=$G8,if(and($F8=$G8,AE8<>AF8),'Thể lệ'!$E$6,if($F8=AE8,0,0.5*'Thể lệ'!$E$6)),if(and($F8=AE8,$G8=AF8),"0",if(($F8-$G8)*(AE8-AF8)>0,0.5*'Thể lệ'!$E$6,'Thể lệ'!$E$6))) -> 10000 | CL8: =if($F8=$G8,if(and($F8=$G8,AG8<>AH8),'Thể lệ'!$E$6,if($F8=AG8,0,0.5*'Thể lệ'!$E$6)),if(and($F8=AG8,$G8=AH8),"0",if(($F8-$G8)*(AG8-AH8)>0,0.5*'Thể lệ'!$E$6,'Thể lệ'!$E$6))) -> 0 | CN8: =if($F8=$G8,if(and($F8=$G8,AI8<>AJ8),'Thể lệ'!$E$6,if($F8=AI8,0,0.5*'Thể lệ'!$E$6)),if(and($F8=AI8,$G8=AJ8),"0",if(($F8-$G8)*(AI8-AJ8)>0,0.5*'Thể lệ'!$E$6,'Thể lệ'!$E$6))) -> 0 | CP8: =if($F8=$G8,if(and($F8=$G8,AK8<>AL8),'Thể lệ'!$E$6,if($F8=AK8,0,0.5*'Thể lệ'!$E$6)),if(and($F8=AK8,$G8=AL8),"0",if(($F8-$G8)*(AK8-AL8)>0,0.5*'Thể lệ'!$E$6,'Thể lệ'!$E$6))) -> 5000 | CR8: =if($F8=$G8,if(and($F8=$G8,AM8<>AN8),'Thể lệ'!$E$6,if($F8=AM8,0,0.5*'Thể lệ'!$E$6)),if(and($F8=AM8,$G8=AN8),"0",if(($F8-$G8)*(AM8-AN8)>0,0.5*'Thể lệ'!$E$6,'Thể lệ'!$E$6))) -> 10000 | CT8: =if($F8=$G8,if(and($F8=$G8,AO8<>AP8),'Thể lệ'!$E$6,if($F8=AO8,0,0.5*'Thể lệ'!$E$6)),if(and($F8=AO8,$G8=AP8),"0",if(($F8-$G8)*(AO8-AP8)>0,0.5*'Thể lệ'!$E$6,'Thể lệ'!$E$6))) -> 10000 | CV8: =if($F8=$G8,if(and($F8=$G8,AQ8<>AR8),'Thể lệ'!$E$6,if($F8=AQ8,0,0.5*'Thể lệ'!$E$6)),if(and($F8=AQ8,$G8=AR8),"0",if(($F8-$G8)*(AQ8-AR8)>0,0.5*'Thể lệ'!$E$6,'Thể lệ'!$E$6))) -> 5000 | CX8: =if($F8=$G8,if(and($F8=$G8,AS8<>AT8),'Thể lệ'!$E$6,if($F8=AS8,0,0.5*'Thể lệ'!$E$6)),if(and($F8=AS8,$G8=AT8),"0",if(($F8-$G8)*(AS8-AT8)>0,0.5*'Thể lệ'!$E$6,'Thể lệ'!$E$6))) -> 5000 | CZ8: =if($F8=$G8,if(and($F8=$G8,AU8<>AV8),'Thể lệ'!$E$6,if($F8=AU8,0,0.5*'Thể lệ'!$E$6)),if(and($F8=AU8,$G8=AV8),"0",if(($F8-$G8)*(AU8-AV8)>0,0.5*'Thể lệ'!$E$6,'Thể lệ'!$E$6))) -> 5000 | DB8: =if($F8=$G8,if(and($F8=$G8,AW8<>AX8),'Thể lệ'!$E$6,if($F8=AW8,0,0.5*'Thể lệ'!$E$6)),if(and($F8=AW8,$G8=AX8),"0",if(($F8-$G8)*(AW8-AX8)>0,0.5*'Thể lệ'!$E$6,'Thể lệ'!$E$6))) -> 10000 | DD8: =if($F8=$G8,if(and($F8=$G8,AY8<>AZ8),'Thể lệ'!$E$6,if($F8=AY8,0,0.5*'Thể lệ'!$E$6)),if(and($F8=AY8,$G8=AZ8),"0",if(($F8-$G8)*(AY8-AZ8)>0,0.5*'Thể lệ'!$E$6,'Thể lệ'!$E$6))) -> 10000 | DF8: =if($F8=$G8,if(and($F8=$G8,BA8<>BB8),'Thể lệ'!$E$6,if($F8=BA8,0,0.5*'Thể lệ'!$E$6)),if(and($F8=BA8,$G8=BB8),"0",if(($F8-$G8)*(BA8-BB8)>0,0.5*'Thể lệ'!$E$6,'Thể lệ'!$E$6))) -> 10000 | DH8: =if($F8=$G8,if(and($F8=$G8,BC8<>BD8),'Thể lệ'!$E$6,if($F8=BC8,0,0.5*'Thể lệ'!$E$6)),if(and($F8=BC8,$G8=BD8),"0",if(($F8-$G8)*(BC8-BD8)>0,0.5*'Thể lệ'!$E$6,'Thể lệ'!$E$6))) -> 10000 | DJ8: =if($F8=$G8,if(and($F8=$G8,BE8<>BF8),'Thể lệ'!$E$6,if($F8=BE8,0,0.5*'Thể lệ'!$E$6)),if(and($F8=BE8,$G8=BF8),"0",if(($F8-$G8)*(BE8-BF8)>0,0.5*'Thể lệ'!$E$6,'Thể lệ'!$E$6))) -> 5000 | DL8: =if($F8=$G8,if(and($F8=$G8,BG8<>BH8),'Thể lệ'!$E$6,if($F8=BG8,0,0.5*'Thể lệ'!$E$6)),if(and($F8=BG8,$G8=BH8),"0",if(($F8-$G8)*(BG8-BH8)>0,0.5*'Thể lệ'!$E$6,'Thể lệ'!$E$6))) -> 0 | DN8: =if($F8=$G8,if(and($F8=$G8,BI8<>BJ8),'Thể lệ'!$E$6,if($F8=BI8,0,0.5*'Thể lệ'!$E$6)),if(and($F8=BI8,$G8=BJ8),"0",if(($F8-$G8)*(BI8-BJ8)>0,0.5*'Thể lệ'!$E$6,'Thể lệ'!$E$6))) -> 5000
B9: 3 | C9: 46186.083 | D9: 46186.083 | E9: Canada | H9: Bosnia/Herzeg. | K9: 1 | L9: 3 | O9: 2 | P9: 1 | Q9: =AE9 -> 1 | R9: 0 | S9: 2 | T9: 1 | U9: 1 | V9: 1 | W9: 1 | X9: 1 | Y9: 0 | Z9: 2 | AC9: 1 | AD9: 0 | AE9: 1 | AF9: 1 | AK9: 0 | AL9: 1 | AM9: 1 | AN9: 1 | AO9: 1 | AP9: 2 | AQ9: 0 | AR9: =BF9 -> 1 | AS9: 1 | AT9: 1 | AU9: 1 | AV9: 0 | AY9: 2 | AZ9: 1 | BA9: 1 | BB9: 1 | BC9: 2 | BD9: 1 | BE9: 2 | BF9: 1 | BI9: =H.Son!H9 -> 2 | BJ9: =H.Son!I9 -> 1 | BN9: =if($F9=$G9,if(and($F9=$G9,I9<>J9),'Thể lệ'!$E$6,if($F9=I9,0,0.5*'Thể lệ'!$E$6)),if(and($F9=I9,$G9=J9),"0",if(($F9-$G9)*(I9-J9)>0,0.5*'Thể lệ'!$E$6,'Thể lệ'!$E$6))) -> 0 | BP9: =if($F9=$G9,if(and($F9=$G9,K9<>L9),'Thể lệ'!$E$6,if($F9=K9,0,0.5*'Thể lệ'!$E$6)),if(and($F9=K9,$G9=L9),"0",if(($F9-$G9)*(K9-L9)>0,0.5*'Thể lệ'!$E$6,'Thể lệ'!$E$6))) -> 10000 | BR9: =if($F9=$G9,if(and($F9=$G9,M9<>N9),'Thể lệ'!$E$6,if($F9=M9,0,0.5*'Thể lệ'!$E$6)),if(and($F9=M9,$G9=N9),"0",if(($F9-$G9)*(M9-N9)>0,0.5*'Thể lệ'!$E$6,'Thể lệ'!$E$6))) -> 0 | BT9: =if($F9=$G9,if(and($F9=$G9,O9<>P9),'Thể lệ'!$E$6,if($F9=O9,0,0.5*'Thể lệ'!$E$6)),if(and($F9=O9,$G9=P9),"0",if(($F9-$G9)*(O9-P9)>0,0.5*'Thể lệ'!$E$6,'Thể lệ'!$E$6))) -> 10000 | BV9: =if($F9=$G9,if(and($F9=$G9,Q9<>R9),'Thể lệ'!$E$6,if($F9=Q9,0,0.5*'Thể lệ'!$E$6)),if(and($F9=Q9,$G9=R9),"0",if(($F9-$G9)*(Q9-R9)>0,0.5*'Thể lệ'!$E$6,'Thể lệ'!$E$6))) -> 10000 | BX9: =if($F9=$G9,if(and($F9=$G9,S9<>T9),'Thể lệ'!$E$6,if($F9=S9,0,0.5*'Thể lệ'!$E$6)),if(and($F9=S9,$G9=T9),"0",if(($F9-$G9)*(S9-T9)>0,0.5*'Thể lệ'!$E$6,'Thể lệ'!$E$6))) -> 10000 | BZ9: =if($F9=$G9,if(and($F9=$G9,U9<>V9),'Thể lệ'!$E$6,if($F9=U9,0,0.5*'Thể lệ'!$E$6)),if(and($F9=U9,$G9=V9),"0",if(($F9-$G9)*(U9-V9)>0,0.5*'Thể lệ'!$E$6,'Thể lệ'!$E$6))) -> 5000 | CB9: =if($F9=$G9,if(and($F9=$G9,W9<>X9),'Thể lệ'!$E$6,if($F9=W9,0,0.5*'Thể lệ'!$E$6)),if(and($F9=W9,$G9=X9),"0",if(($F9-$G9)*(W9-X9)>0,0.5*'Thể lệ'!$E$6,'Thể lệ'!$E$6))) -> 5000 | CD9: =if($F9=$G9,if(and($F9=$G9,Y9<>Z9),'Thể lệ'!$E$6,if($F9=Y9,0,0.5*'Thể lệ'!$E$6)),if(and($F9=Y9,$G9=Z9),"0",if(($F9-$G9)*(Y9-Z9)>0,0.5*'Thể lệ'!$E$6,'Thể lệ'!$E$6))) -> 10000 | CF9: =if($F9=$G9,if(and($F9=$G9,AA9<>AB9),'Thể lệ'!$E$6,if($F9=AA9,0,0.5*'Thể lệ'!$E$6)),if(and($F9=AA9,$G9=AB9),"0",if(($F9-$G9)*(AA9-AB9)>0,0.5*'Thể lệ'!$E$6,'Thể lệ'!$E$6))) -> 0 | CH9: =if($F9=$G9,if(and($F9=$G9,AC9<>AD9),'Thể lệ'!$E$6,if($F9=AC9,0,0.5*'Thể lệ'!$E$6)),if(and($F9=AC9,$G9=AD9),"0",if(($F9-$G9)*(AC9-AD9)>0,0.5*'Thể lệ'!$E$6,'Thể lệ'!$E$6))) -> 10000 | CJ9: =if($F9=$G9,if(and($F9=$G9,AE9<>AF9),'Thể lệ'!$E$6,if($F9=AE9,0,0.5*'Thể lệ'!$E$6)),if(and($F9=AE9,$G9=AF9),"0",if(($F9-$G9)*(AE9-AF9)>0,0.5*'Thể lệ'!$E$6,'Thể lệ'!$E$6))) -> 5000 | CL9: =if($F9=$G9,if(and($F9=$G9,AG9<>AH9),'Thể lệ'!$E$6,if($F9=AG9,0,0.5*'Thể lệ'!$E$6)),if(and($F9=AG9,$G9=AH9),"0",if(($F9-$G9)*(AG9-AH9)>0,0.5*'Thể lệ'!$E$6,'Thể lệ'!$E$6))) -> 0 | CN9: =if($F9=$G9,if(and($F9=$G9,AI9<>AJ9),'Thể lệ'!$E$6,if($F9=AI9,0,0.5*'Thể lệ'!$E$6)),if(and($F9=AI9,$G9=AJ9),"0",if(($F9-$G9)*(AI9-AJ9)>0,0.5*'Thể lệ'!$E$6,'Thể lệ'!$E$6))) -> 0 | CP9: =if($F9=$G9,if(and($F9=$G9,AK9<>AL9),'Thể lệ'!$E$6,if($F9=AK9,0,0.5*'Thể lệ'!$E$6)),if(and($F9=AK9,$G9=AL9),"0",if(($F9-$G9)*(AK9-AL9)>0,0.5*'Thể lệ'!$E$6,'Thể lệ'!$E$6))) -> 10000 | CR9: =if($F9=$G9,if(and($F9=$G9,AM9<>AN9),'Thể lệ'!$E$6,if($F9=AM9,0,0.5*'Thể lệ'!$E$6)),if(and($F9=AM9,$G9=AN9),"0",if(($F9-$G9)*(AM9-AN9)>0,0.5*'Thể lệ'!$E$6,'Thể lệ'!$E$6))) -> 5000 | CT9: =if($F9=$G9,if(and($F9=$G9,AO9<>AP9),'Thể lệ'!$E$6,if($F9=AO9,0,0.5*'Thể lệ'!$E$6)),if(and($F9=AO9,$G9=AP9),"0",if(($F9-$G9)*(AO9-AP9)>0,0.5*'Thể lệ'!$E$6,'Thể lệ'!$E$6))) -> 10000 | CV9: =if($F9=$G9,if(and($F9=$G9,AQ9<>AR9),'Thể lệ'!$E$6,if($F9=AQ9,0,0.5*'Thể lệ'!$E$6)),if(and($F9=AQ9,$G9=AR9),"0",if(($F9-$G9)*(AQ9-AR9)>0,0.5*'Thể lệ'!$E$6,'Thể lệ'!$E$6))) -> 10000 | CX9: =if($F9=$G9,if(and($F9=$G9,AS9<>AT9),'Thể lệ'!$E$6,if($F9=AS9,0,0.5*'Thể lệ'!$E$6)),if(and($F9=AS9,$G9=AT9),"0",if(($F9-$G9)*(AS9-AT9)>0,0.5*'Thể lệ'!$E$6,'Thể lệ'!$E$6))) -> 5000 | CZ9: =if($F9=$G9,if(and($F9=$G9,AU9<>AV9),'Thể lệ'!$E$6,if($F9=AU9,0,0.5*'Thể lệ'!$E$6)),if(and($F9=AU9,$G9=AV9),"0",if(($F9-$G9)*(AU9-AV9)>0,0.5*'Thể lệ'!$E$6,'Thể lệ'!$E$6))) -> 10000 | DB9: =if($F9=$G9,if(and($F9=$G9,AW9<>AX9),'Thể lệ'!$E$6,if($F9=AW9,0,0.5*'Thể lệ'!$E$6)),if(and($F9=AW9,$G9=AX9),"0",if(($F9-$G9)*(AW9-AX9)>0,0.5*'Thể lệ'!$E$6,'Thể lệ'!$E$6))) -> 0 | DD9: =if($F9=$G9,if(and($F9=$G9,AY9<>AZ9),'Thể lệ'!$E$6,if($F9=AY9,0,0.5*'Thể lệ'!$E$6)),if(and($F9=AY9,$G9=AZ9),"0",if(($F9-$G9)*(AY9-AZ9)>0,0.5*'Thể lệ'!$E$6,'Thể lệ'!$E$6))) -> 10000 | DF9: =if($F9=$G9,if(and($F9=$G9,BA9<>BB9),'Thể lệ'!$E$6,if($F9=BA9,0,0.5*'Thể lệ'!$E$6)),if(and($F9=BA9,$G9=BB9),"0",if(($F9-$G9)*(BA9-BB9)>0,0.5*'Thể lệ'!$E$6,'Thể lệ'!$E$6))) -> 5000 | DH9: =if($F9=$G9,if(and($F9=$G9,BC9<>BD9),'Thể lệ'!$E$6,if($F9=BC9,0,0.5*'Thể lệ'!$E$6)),if(and($F9=BC9,$G9=BD9),"0",if(($F9-$G9)*(BC9-BD9)>0,0.5*'Thể lệ'!$E$6,'Thể lệ'!$E$6))) -> 10000 | DJ9: =if($F9=$G9,if(and($F9=$G9,BE9<>BF9),'Thể lệ'!$E$6,if($F9=BE9,0,0.5*'Thể lệ'!$E$6)),if(and($F9=BE9,$G9=BF9),"0",if(($F9-$G9)*(BE9-BF9)>0,0.5*'Thể lệ'!$E$6,'Thể lệ'!$E$6))) -> 10000 | DL9: =if($F9=$G9,if(and($F9=$G9,BG9<>BH9),'Thể lệ'!$E$6,if($F9=BG9,0,0.5*'Thể lệ'!$E$6)),if(and($F9=BG9,$G9=BH9),"0",if(($F9-$G9)*(BG9-BH9)>0,0.5*'Thể lệ'!$E$6,'Thể lệ'!$E$6))) -> 0 | DN9: =if($F9=$G9,if(and($F9=$G9,BI9<>BJ9),'Thể lệ'!$E$6,if($F9=BI9,0,0.5*'Thể lệ'!$E$6)),if(and($F9=BI9,$G9=BJ9),"0",if(($F9-$G9)*(BI9-BJ9)>0,0.5*'Thể lệ'!$E$6,'Thể lệ'!$E$6))) -> 10000
B10: 4 | C10: 46186.333 | D10: 46186.333 | E10: USA | H10: Paraguay | K10: 1 | L10: 2 | O10: 2 | P10: 1 | Q10: =AE10 -> 1 | R10: =AF10 -> 1 | S10: 2 | T10: 1 | U10: 0 | V10: 0 | W10: 0 | X10: 0 | Y10: 1 | Z10: 3 | AC10: 0 | AD10: 2 | AE10: 1 | AF10: 1 | AK10: 1 | AL10: 2 | AM10: 1 | AN10: 2 | AO10: 1 | AP10: 3 | AQ10: =BE10 -> 2 | AR10: =BF10 -> 1 | AS10: 2 | AT10: 0 | AU10: 2 | AV10: 1 | AY10: 0 | AZ10: 1 | BA10: 2 | BB10: 1 | BC10: 2 | BD10: 0 | BE10: 2 | BF10: 1 | BI10: =H.Son!H10 -> 2 | BJ10: =H.Son!I10 -> 0 | BN10: =if($F10=$G10,if(and($F10=$G10,I10<>J10),'Thể lệ'!$E$6,if($F10=I10,0,0.5*'Thể lệ'!$E$6)),if(and($F10=I10,$G10=J10),"0",if(($F10-$G10)*(I10-J10)>0,0.5*'Thể lệ'!$E$6,'Thể lệ'!$E$6))) -> 0 | BP10: =if($F10=$G10,if(and($F10=$G10,K10<>L10),'Thể lệ'!$E$6,if($F10=K10,0,0.5*'Thể lệ'!$E$6)),if(and($F10=K10,$G10=L10),"0",if(($F10-$G10)*(K10-L10)>0,0.5*'Thể lệ'!$E$6,'Thể lệ'!$E$6))) -> 10000 | BR10: =if($F10=$G10,if(and($F10=$G10,M10<>N10),'Thể lệ'!$E$6,if($F10=M10,0,0.5*'Thể lệ'!$E$6)),if(and($F10=M10,$G10=N10),"0",if(($F10-$G10)*(M10-N10)>0,0.5*'Thể lệ'!$E$6,'Thể lệ'!$E$6))) -> 0 | BT10: =if($F10=$G10,if(and($F10=$G10,O10<>P10),'Thể lệ'!$E$6,if($F10=O10,0,0.5*'Thể lệ'!$E$6)),if(and($F10=O10,$G10=P10),"0",if(($F10-$G10)*(O10-P10)>0,0.5*'Thể lệ'!$E$6,'Thể lệ'!$E$6))) -> 10000 | BV10: =if($F10=$G10,if(and($F10=$G10,Q10<>R10),'Thể lệ'!$E$6,if($F10=Q10,0,0.5*'Thể lệ'!$E$6)),if(and($F10=Q10,$G10=R10),"0",if(($F10-$G10)*(Q10-R10)>0,0.5*'Thể lệ'!$E$6,'Thể lệ'!$E$6))) -> 5000 | BX10: =if($F10=$G10,if(and($F10=$G10,S10<>T10),'Thể lệ'!$E$6,if($F10=S10,0,0.5*'Thể lệ'!$E$6)),if(and($F10=S10,$G10=T10),"0",if(($F10-$G10)*(S10-T10)>0,0.5*'Thể lệ'!$E$6,'Thể lệ'!$E$6))) -> 10000 | BZ10: =if($F10=$G10,if(and($F10=$G10,U10<>V10),'Thể lệ'!$E$6,if($F10=U10,0,0.5*'Thể lệ'!$E$6)),if(and($F10=U10,$G10=V10),"0",if(($F10-$G10)*(U10-V10)>0,0.5*'Thể lệ'!$E$6,'Thể lệ'!$E$6))) -> 0 | CB10: =if($F10=$G10,if(and($F10=$G10,W10<>X10),'Thể lệ'!$E$6,if($F10=W10,0,0.5*'Thể lệ'!$E$6)),if(and($F10=W10,$G10=X10),"0",if(($F10-$G10)*(W10-X10)>0,0.5*'Thể lệ'!$E$6,'Thể lệ'!$E$6))) -> 0 | CD10: =if($F10=$G10,if(and($F10=$G10,Y10<>Z10),'Thể lệ'!$E$6,if($F10=Y10,0,0.5*'Thể lệ'!$E$6)),if(and($F10=Y10,$G10=Z10),"0",if(($F10-$G10)*(Y10-Z10)>0,0.5*'Thể lệ'!$E$6,'Thể lệ'!$E$6))) -> 10000 | CF10: =if($F10=$G10,if(and($F10=$G10,AA10<>AB10),'Thể lệ'!$E$6,if($F10=AA10,0,0.5*'Thể lệ'!$E$6)),if(and($F10=AA10,$G10=AB10),"0",if(($F10-$G10)*(AA10-AB10)>0,0.5*'Thể lệ'!$E$6,'Thể lệ'!$E$6))) -> 0 | CH10: =if($F10=$G10,if(and($F10=$G10,AC10<>AD10),'Thể lệ'!$E$6,if($F10=AC10,0,0.5*'Thể lệ'!$E$6)),if(and($F10=AC10,$G10=AD10),"0",if(($F10-$G10)*(AC10-AD10)>0,0.5*'Thể lệ'!$E$6,'Thể lệ'!$E$6))) -> 10000 | CJ10: =if($F10=$G10,if(and($F10=$G10,AE10<>AF10),'Thể lệ'!$E$6,if($F10=AE10,0,0.5*'Thể lệ'!$E$6)),if(and($F10=AE10,$G10=AF10),"0",if(($F10-$G10)*(AE10-AF10)>0,0.5*'Thể lệ'!$E$6,'Thể lệ'!$E$6))) -> 5000 | CL10: =if($F10=$G10,if(and($F10=$G10,AG10<>AH10),'Thể lệ'!$E$6,if($F10=AG10,0,0.5*'Thể lệ'!$E$6)),if(and($F10=AG10,$G10=AH10),"0",if(($F10-$G10)*(AG10-AH10)>0,0.5*'Thể lệ'!$E$6,'Thể lệ'!$E$6))) -> 0 | CN10: =if($F10=$G10,if(and($F10=$G10,AI10<>AJ10),'Thể lệ'!$E$6,if($F10=AI10,0,0.5*'Thể lệ'!$E$6)),if(and($F10=AI10,$G10=AJ10),"0",if(($F10-$G10)*(AI10-AJ10)>0,0.5*'Thể lệ'!$E$6,'Thể lệ'!$E$6))) -> 0 | CP10: =if($F10=$G10,if(and($F10=$G10,AK10<>AL10),'Thể lệ'!$E$6,if($F10=AK10,0,0.5*'Thể lệ'!$E$6)),if(and($F10=AK10,$G10=AL10),"0",if(($F10-$G10)*(AK10-AL10)>0,0.5*'Thể lệ'!$E$6,'Thể lệ'!$E$6))) -> 10000 | CR10: =if($F10=$G10,if(and($F10=$G10,AM10<>AN10),'Thể lệ'!$E$6,if($F10=AM10,0,0.5*'Thể lệ'!$E$6)),if(and($F10=AM10,$G10=AN10),"0",if(($F10-$G10)*(AM10-AN10)>0,0.5*'Thể lệ'!$E$6,'Thể lệ'!$E$6))) -> 10000 | CT10: =if($F10=$G10,if(and($F10=$G10,AO10<>AP10),'Thể lệ'!$E$6,if($F10=AO10,0,0.5*'Thể lệ'!$E$6)),if(and($F10=AO10,$G10=AP10),"0",if(($F10-$G10)*(AO10-AP10)>0,0.5*'Thể lệ'!$E$6,'Thể lệ'!$E$6))) -> 10000 | CV10: =if($F10=$G10,if(and($F10=$G10,AQ10<>AR10),'Thể lệ'!$E$6,if($F10=AQ10,0,0.5*'Thể lệ'!$E$6)),if(and($F10=AQ10,$G10=AR10),"0",if(($F10-$G10)*(AQ10-AR10)>0,0.5*'Thể lệ'!$E$6,'Thể lệ'!$E$6))) -> 10000 | CX10: =if($F10=$G10,if(and($F10=$G10,AS10<>AT10),'Thể lệ'!$E$6,if($F10=AS10,0,0.5*'Thể lệ'!$E$6)),if(and($F10=AS10,$G10=AT10),"0",if(($F10-$G10)*(AS10-AT10)>0,0.5*'Thể lệ'!$E$6,'Thể lệ'!$E$6))) -> 10000 | CZ10: =if($F10=$G10,if(and($F10=$G10,AU10<>AV10),'Thể lệ'!$E$6,if($F10=AU10,0,0.5*'Thể lệ'!$E$6)),if(and($F10=AU10,$G10=AV10),"0",if(($F10-$G10)*(AU10-AV10)>0,0.5*'Thể lệ'!$E$6,'Thể lệ'!$E$6))) -> 10000 | DB10: =if($F10=$G10,if(and($F10=$G10,AW10<>AX10),'Thể lệ'!$E$6,if($F10=AW10,0,0.5*'Thể lệ'!$E$6)),if(and($F10=AW10,$G10=AX10),"0",if(($F10-$G10)*(AW10-AX10)>0,0.5*'Thể lệ'!$E$6,'Thể lệ'!$E$6))) -> 0 | DD10: =if($F10=$G10,if(and($F10=$G10,AY10<>AZ10),'Thể lệ'!$E$6,if($F10=AY10,0,0.5*'Thể lệ'!$E$6)),if(and($F10=AY10,$G10=AZ10),"0",if(($F10-$G10)*(AY10-AZ10)>0,0.5*'Thể lệ'!$E$6,'Thể lệ'!$E$6))) -> 10000 | DF10: =if($F10=$G10,if(and($F10=$G10,BA10<>BB10),'Thể lệ'!$E$6,if($F10=BA10,0,0.5*'Thể lệ'!$E$6)),if(and($F10=BA10,$G10=BB10),"0",if(($F10-$G10)*(BA10-BB10)>0,0.5*'Thể lệ'!$E$6,'Thể lệ'!$E$6))) -> 10000 | DH10: =if($F10=$G10,if(and($F10=$G10,BC10<>BD10),'Thể lệ'!$E$6,if($F10=BC10,0,0.5*'Thể lệ'!$E$6)),if(and($F10=BC10,$G10=BD10),"0",if(($F10-$G10)*(BC10-BD10)>0,0.5*'Thể lệ'!$E$6,'Thể lệ'!$E$6))) -> 10000 | DJ10: =if($F10=$G10,if(and($F10=$G10,BE10<>BF10),'Thể lệ'!$E$6,if($F10=BE10,0,0.5*'Thể lệ'!$E$6)),if(and($F10=BE10,$G10=BF10),"0",if(($F10-$G10)*(BE10-BF10)>0,0.5*'Thể lệ'!$E$6,'Thể lệ'!$E$6))) -> 10000 | DL10: =if($F10=$G10,if(and($F10=$G10,BG10<>BH10),'Thể lệ'!$E$6,if($F10=BG10,0,0.5*'Thể lệ'!$E$6)),if(and($F10=BG10,$G10=BH10),"0",if(($F10-$G10)*(BG10-BH10)>0,0.5*'Thể lệ'!$E$6,'Thể lệ'!$E$6))) -> 0 | DN10: =if($F10=$G10,if(and($F10=$G10,BI10<>BJ10),'Thể lệ'!$E$6,if($F10=BI10,0,0.5*'Thể lệ'!$E$6)),if(and($F10=BI10,$G10=BJ10),"0",if(($F10-$G10)*(BI10-BJ10)>0,0.5*'Thể lệ'!$E$6,'Thể lệ'!$E$6))) -> 10000
B11: 5 | C11: 46187.083 | D11: 46187.083 | E11: Qatar | H11: Switzerland | K11: 2 | L11: 3 | O11: 0 | P11: 2 | Q11: =AE11 -> 1 | R11: =AF11 -> 1 | S11: 0 | T11: 2 | U11: 1 | V11: 2 | W11: 1 | X11: 2 | Y11: 0 | Z11: 3 | AE11: 1 | AF11: 1 | AK11: 0 | AL11: 1 | AM11: 0 | AN11: 2 | AO11: 1 | AP11: 2 | AQ11: =BE11 -> 0 | AR11: =BF11 -> 1 | AS11: 0 | AT11: 2 | AU11: 0 | AV11: 2 | AY11: 0 | AZ11: 1 | BA11: 0 | BB11: 1 | BC11: 0 | BD11: 3 | BE11: 0 | BF11: 1 | BI11: =H.Son!H11 -> 0 | BJ11: =H.Son!I11 -> 2 | BN11: =if($F11=$G11,if(and($F11=$G11,I11<>J11),'Thể lệ'!$E$6,if($F11=I11,0,0.5*'Thể lệ'!$E$6)),if(and($F11=I11,$G11=J11),"0",if(($F11-$G11)*(I11-J11)>0,0.5*'Thể lệ'!$E$6,'Thể lệ'!$E$6))) -> 0 | BP11: =if($F11=$G11,if(and($F11=$G11,K11<>L11),'Thể lệ'!$E$6,if($F11=K11,0,0.5*'Thể lệ'!$E$6)),if(and($F11=K11,$G11=L11),"0",if(($F11-$G11)*(K11-L11)>0,0.5*'Thể lệ'!$E$6,'Thể lệ'!$E$6))) -> 10000 | BR11: =if($F11=$G11,if(and($F11=$G11,M11<>N11),'Thể lệ'!$E$6,if($F11=M11,0,0.5*'Thể lệ'!$E$6)),if(and($F11=M11,$G11=N11),"0",if(($F11-$G11)*(M11-N11)>0,0.5*'Thể lệ'!$E$6,'Thể lệ'!$E$6))) -> 0 | BT11: =if($F11=$G11,if(and($F11=$G11,O11<>P11),'Thể lệ'!$E$6,if($F11=O11,0,0.5*'Thể lệ'!$E$6)),if(and($F11=O11,$G11=P11),"0",if(($F11-$G11)*(O11-P11)>0,0.5*'Thể lệ'!$E$6,'Thể lệ'!$E$6))) -> 10000 | BV11: =if($F11=$G11,if(and($F11=$G11,Q11<>R11),'Thể lệ'!$E$6,if($F11=Q11,0,0.5*'Thể lệ'!$E$6)),if(and($F11=Q11,$G11=R11),"0",if(($F11-$G11)*(Q11-R11)>0,0.5*'Thể lệ'!$E$6,'Thể lệ'!$E$6))) -> 5000 | BX11: =if($F11=$G11,if(and($F11=$G11,S11<>T11),'Thể lệ'!$E$6,if($F11=S11,0,0.5*'Thể lệ'!$E$6)),if(and($F11=S11,$G11=T11),"0",if(($F11-$G11)*(S11-T11)>0,0.5*'Thể lệ'!$E$6,'Thể lệ'!$E$6))) -> 10000 | BZ11: =if($F11=$G11,if(and($F11=$G11,U11<>V11),'Thể lệ'!$E$6,if($F11=U11,0,0.5*'Thể lệ'!$E$6)),if(and($F11=U11,$G11=V11),"0",if(($F11-$G11)*(U11-V11)>0,0.5*'Thể lệ'!$E$6,'Thể lệ'!$E$6))) -> 10000 | CB11: =if($F11=$G11,if(and($F11=$G11,W11<>X11),'Thể lệ'!$E$6,if($F11=W11,0,0.5*'Thể lệ'!$E$6)),if(and($F11=W11,$G11=X11),"0",if(($F11-$G11)*(W11-X11)>0,0.5*'Thể lệ'!$E$6,'Thể lệ'!$E$6))) -> 10000 | CD11: =if($F11=$G11,if(and($F11=$G11,Y11<>Z11),'Thể lệ'!$E$6,if($F11=Y11,0,0.5*'Thể lệ'!$E$6)),if(and($F11=Y11,$G11=Z11),"0",if(($F11-$G11)*(Y11-Z11)>0,0.5*'Thể lệ'!$E$6,'Thể lệ'!$E$6))) -> 10000 | CF11: =if($F11=$G11,if(and($F11=$G11,AA11<>AB11),'Thể lệ'!$E$6,if($F11=AA11,0,0.5*'Thể lệ'!$E$6)),if(and($F11=AA11,$G11=AB11),"0",if(($F11-$G11)*(AA11-AB11)>0,0.5*'Thể lệ'!$E$6,'Thể lệ'!$E$6))) -> 0 | CH11: =if($F11=$G11,if(and($F11=$G11,AC11<>AD11),'Thể lệ'!$E$6,if($F11=AC11,0,0.5*'Thể lệ'!$E$6)),if(and($F11=AC11,$G11=AD11),"0",if(($F11-$G11)*(AC11-AD11)>0,0.5*'Thể lệ'!$E$6,'Thể lệ'!$E$6))) -> 0 | CJ11: =if($F11=$G11,if(and($F11=$G11,AE11<>AF11),'Thể lệ'!$E$6,if($F11=AE11,0,0.5*'Thể lệ'!$E$6)),if(and($F11=AE11,$G11=AF11),"0",if(($F11-$G11)*(AE11-AF11)>0,0.5*'Thể lệ'!$E$6,'Thể lệ'!$E$6))) -> 5000 | CL11: =if($F11=$G11,if(and($F11=$G11,AG11<>AH11),'Thể lệ'!$E$6,if($F11=AG11,0,0.5*'Thể lệ'!$E$6)),if(and($F11=AG11,$G11=AH11),"0",if(($F11-$G11)*(AG11-AH11)>0,0.5*'Thể lệ'!$E$6,'Thể lệ'!$E$6))) -> 0 | CN11: =if($F11=$G11,if(and($F11=$G11,AI11<>AJ11),'Thể lệ'!$E$6,if($F11=AI11,0,0.5*'Thể lệ'!$E$6)),if(and($F11=AI11,$G11=AJ11),"0",if(($F11-$G11)*(AI11-AJ11)>0,0.5*'Thể lệ'!$E$6,'Thể lệ'!$E$6))) -> 0 | CP11: =if($F11=$G11,if(and($F11=$G11,AK11<>AL11),'Thể lệ'!$E$6,if($F11=AK11,0,0.5*'Thể lệ'!$E$6)),if(and($F11=AK11,$G11=AL11),"0",if(($F11-$G11)*(AK11-AL11)>0,0.5*'Thể lệ'!$E$6,'Thể lệ'!$E$6))) -> 10000 | CR11: =if($F11=$G11,if(and($F11=$G11,AM11<>AN11),'Thể lệ'!$E$6,if($F11=AM11,0,0.5*'Thể lệ'!$E$6)),if(and($F11=AM11,$G11=AN11),"0",if(($F11-$G11)*(AM11-AN11)>0,0.5*'Thể lệ'!$E$6,'Thể lệ'!$E$6))) -> 10000 | CT11: =if($F11=$G11,if(and($F11=$G11,AO11<>AP11),'Thể lệ'!$E$6,if($F11=AO11,0,0.5*'Thể lệ'!$E$6)),if(and($F11=AO11,$G11=AP11),"0",if(($F11-$G11)*(AO11-AP11)>0,0.5*'Thể lệ'!$E$6,'Thể lệ'!$E$6))) -> 10000 | CV11: =if($F11=$G11,if(and($F11=$G11,AQ11<>AR11),'Thể lệ'!$E$6,if($F11=AQ11,0,0.5*'Thể lệ'!$E$6)),if(and($F11=AQ11,$G11=AR11),"0",if(($F11-$G11)*(AQ11-AR11)>0,0.5*'Thể lệ'!$E$6,'Thể lệ'!$E$6))) -> 10000 | CX11: =if($F11=$G11,if(and($F11=$G11,AS11<>AT11),'Thể lệ'!$E$6,if($F11=AS11,0,0.5*'Thể lệ'!$E$6)),if(and($F11=AS11,$G11=AT11),"0",if(($F11-$G11)*(AS11-AT11)>0,0.5*'Thể lệ'!$E$6,'Thể lệ'!$E$6))) -> 10000 | CZ11: =if($F11=$G11,if(and($F11=$G11,AU11<>AV11),'Thể lệ'!$E$6,if($F11=AU11,0,0.5*'Thể lệ'!$E$6)),if(and($F11=AU11,$G11=AV11),"0",if(($F11-$G11)*(AU11-AV11)>0,0.5*'Thể lệ'!$E$6,'Thể lệ'!$E$6))) -> 10000 | DB11: =if($F11=$G11,if(and($F11=$G11,AW11<>AX11),'Thể lệ'!$E$6,if($F11=AW11,0,0.5*'Thể lệ'!$E$6)),if(and($F11=AW11,$G11=AX11),"0",if(($F11-$G11)*(AW11-AX11)>0,0.5*'Thể lệ'!$E$6,'Thể lệ'!$E$6))) -> 0 | DD11: =if($F11=$G11,if(and($F11=$G11,AY11<>AZ11),'Thể lệ'!$E$6,if($F11=AY11,0,0.5*'Thể lệ'!$E$6)),if(and($F11=AY11,$G11=AZ11),"0",if(($F11-$G11)*(AY11-AZ11)>0,0.5*'Thể lệ'!$E$6,'Thể lệ'!$E$6))) -> 10000 | DF11: =if($F11=$G11,if(and($F11=$G11,BA11<>BB11),'Thể lệ'!$E$6,if($F11=BA11,0,0.5*'Thể lệ'!$E$6)),if(and($F11=BA11,$G11=BB11),"0",if(($F11-$G11)*(BA11-BB11)>0,0.5*'Thể lệ'!$E$6,'Thể lệ'!$E$6))) -> 10000 | DH11: =if($F11=$G11,if(and($F11=$G11,BC11<>BD11),'Thể lệ'!$E$6,if($F11=BC11,0,0.5*'Thể lệ'!$E$6)),if(and($F11=BC11,$G11=BD11),"0",if(($F11-$G11)*(BC11-BD11)>0,0.5*'Thể lệ'!$E$6,'Thể lệ'!$E$6))) -> 10000 | DJ11: =if($F11=$G11,if(and($F11=$G11,BE11<>BF11),'Thể lệ'!$E$6,if($F11=BE11,0,0.5*'Thể lệ'!$E$6)),if(and($F11=BE11,$G11=BF11),"0",if(($F11-$G11)*(BE11-BF11)>0,0.5*'Thể lệ'!$E$6,'Thể lệ'!$E$6))) -> 10000 | DL11: =if($F11=$G11,if(and($F11=$G11,BG11<>BH11),'Thể lệ'!$E$6,if($F11=BG11,0,0.5*'Thể lệ'!$E$6)),if(and($F11=BG11,$G11=BH11),"0",if(($F11-$G11)*(BG11-BH11)>0,0.5*'Thể lệ'!$E$6,'Thể lệ'!$E$6))) -> 0 | DN11: =if($F11=$G11,if(and($F11=$G11,BI11<>BJ11),'Thể lệ'!$E$6,if($F11=BI11,0,0.5*'Thể lệ'!$E$6)),if(and($F11=BI11,$G11=BJ11),"0",if(($F11-$G11)*(BI11-BJ11)>0,0.5*'Thể lệ'!$E$6,'Thể lệ'!$E$6))) -> 10000
B12: 6 | C12: 46187.208 | D12: 46187.208 | E12: Brazil | H12: Morocco | K12: 3 | L12: 1 | O12: 3 | P12: 1 | Q12: =AE12 -> 1 | R12: =AF12 -> 1 | S12: 2 | T12: 1 | U12: 2 | V12: 0 | W12: 2 | X12: 0 | Y12: 1 | Z12: 1 | AE12: 1 | AF12: 1 | AK12: 2 | AL12: 0 | AO12: 2 | AP12: 2 | AQ12: =BE12 -> 2 | AR12: =BF12 -> 1 | AS12: 3 | AT12: 0 | AU12: 2 | AV12: 1 | AY12: 2 | AZ12: 0 | BA12: 1 | BB12: 2 | BC12: 2 | BD12: 1 | BE12: 2 | BF12: 1 | BI12: =H.Son!H12 -> 2 | BJ12: =H.Son!I12 -> 0 | BN12: =if($F12=$G12,if(and($F12=$G12,I12<>J12),'Thể lệ'!$E$6,if($F12=I12,0,0.5*'Thể lệ'!$E$6)),if(and($F12=I12,$G12=J12),"0",if(($F12-$G12)*(I12-J12)>0,0.5*'Thể lệ'!$E$6,'Thể lệ'!$E$6))) -> 0 | BP12: =if($F12=$G12,if(and($F12=$G12,K12<>L12),'Thể lệ'!$E$6,if($F12=K12,0,0.5*'Thể lệ'!$E$6)),if(and($F12=K12,$G12=L12),"0",if(($F12-$G12)*(K12-L12)>0,0.5*'Thể lệ'!$E$6,'Thể lệ'!$E$6))) -> 10000 | BR12: =if($F12=$G12,if(and($F12=$G12,M12<>N12),'Thể lệ'!$E$6,if($F12=M12,0,0.5*'Thể lệ'!$E$6)),if(and($F12=M12,$G12=N12),"0",if(($F12-$G12)*(M12-N12)>0,0.5*'Thể lệ'!$E$6,'Thể lệ'!$E$6))) -> 0 | BT12: =if($F12=$G12,if(and($F12=$G12,O12<>P12),'Thể lệ'!$E$6,if($F12=O12,0,0.5*'Thể lệ'!$E$6)),if(and($F12=O12,$G12=P12),"0",if(($F12-$G12)*(O12-P12)>0,0.5*'Thể lệ'!$E$6,'Thể lệ'!$E$6))) -> 10000 | BV12: =if($F12=$G12,if(and($F12=$G12,Q12<>R12),'Thể lệ'!$E$6,if($F12=Q12,0,0.5*'Thể lệ'!$E$6)),if(and($F12=Q12,$G12=R12),"0",if(($F12-$G12)*(Q12-R12)>0,0.5*'Thể lệ'!$E$6,'Thể lệ'!$E$6))) -> 5000 | BX12: =if($F12=$G12,if(and($F12=$G12,S12<>T12),'Thể lệ'!$E$6,if($F12=S12,0,0.5*'Thể lệ'!$E$6)),if(and($F12=S12,$G12=T12),"0",if(($F12-$G12)*(S12-T12)>0,0.5*'Thể lệ'!$E$6,'Thể lệ'!$E$6))) -> 10000 | BZ12: =if($F12=$G12,if(and($F12=$G12,U12<>V12),'Thể lệ'!$E$6,if($F12=U12,0,0.5*'Thể lệ'!$E$6)),if(and($F12=U12,$G12=V12),"0",if(($F12-$G12)*(U12-V12)>0,0.5*'Thể lệ'!$E$6,'Thể lệ'!$E$6))) -> 10000 | CB12: =if($F12=$G12,if(and($F12=$G12,W12<>X12),'Thể lệ'!$E$6,if($F12=W12,0,0.5*'Thể lệ'!$E$6)),if(and($F12=W12,$G12=X12),"0",if(($F12-$G12)*(W12-X12)>0,0.5*'Thể lệ'!$E$6,'Thể lệ'!$E$6))) -> 10000 | CD12: =if($F12=$G12,if(and($F12=$G12,Y12<>Z12),'Thể lệ'!$E$6,if($F12=Y12,0,0.5*'Thể lệ'!$E$6)),if(and($F12=Y12,$G12=Z12),"0",if(($F12-$G12)*(Y12-Z12)>0,0.5*'Thể lệ'!$E$6,'Thể lệ'!$E$6))) -> 5000 | CF12: =if($F12=$G12,if(and($F12=$G12,AA12<>AB12),'Thể lệ'!$E$6,if($F12=AA12,0,0.5*'Thể lệ'!$E$6)),if(and($F12=AA12,$G12=AB12),"0",if(($F12-$G12)*(AA12-AB12)>0,0.5*'Thể lệ'!$E$6,'Thể lệ'!$E$6))) -> 0 | CH12: =if($F12=$G12,if(and($F12=$G12,AC12<>AD12),'Thể lệ'!$E$6,if($F12=AC12,0,0.5*'Thể lệ'!$E$6)),if(and($F12=AC12,$G12=AD12),"0",if(($F12-$G12)*(AC12-AD12)>0,0.5*'Thể lệ'!$E$6,'Thể lệ'!$E$6))) -> 0 | CJ12: =if($F12=$G12,if(and($F12=$G12,AE12<>AF12),'Thể lệ'!$E$6,if($F12=AE12,0,0.5*'Thể lệ'!$E$6)),if(and($F12=AE12,$G12=AF12),"0",if(($F12-$G12)*(AE12-AF12)>0,0.5*'Thể lệ'!$E$6,'Thể lệ'!$E$6))) -> 5000 | CL12: =if($F12=$G12,if(and($F12=$G12,AG12<>AH12),'Thể lệ'!$E$6,if($F12=AG12,0,0.5*'Thể lệ'!$E$6)),if(and($F12=AG12,$G12=AH12),"0",if(($F12-$G12)*(AG12-AH12)>0,0.5*'Thể lệ'!$E$6,'Thể lệ'!$E$6))) -> 0 | CN12: =if($F12=$G12,if(and($F12=$G12,AI12<>AJ12),'Thể lệ'!$E$6,if($F12=AI12,0,0.5*'Thể lệ'!$E$6)),if(and($F12=AI12,$G12=AJ12),"0",if(($F12-$G12)*(AI12-AJ12)>0,0.5*'Thể lệ'!$E$6,'Thể lệ'!$E$6))) -> 0 | CP12: =if($F12=$G12,if(and($F12=$G12,AK12<>AL12),'Thể lệ'!$E$6,if($F12=AK12,0,0.5*'Thể lệ'!$E$6)),if(and($F12=AK12,$G12=AL12),"0",if(($F12-$G12)*(AK12-AL12)>0,0.5*'Thể lệ'!$E$6,'Thể lệ'!$E$6))) -> 10000 | CR12: =if($F12=$G12,if(and($F12=$G12,AM12<>AN12),'Thể lệ'!$E$6,if($F12=AM12,0,0.5*'Thể lệ'!$E$6)),if(and($F12=AM12,$G12=AN12),"0",if(($F12-$G12)*(AM12-AN12)>0,0.5*'Thể lệ'!$E$6,'Thể lệ'!$E$6))) -> 0 | CT12: =if($F12=$G12,if(and($F12=$G12,AO12<>AP12),'Thể lệ'!$E$6,if($F12=AO12,0,0.5*'Thể lệ'!$E$6)),if(and($F12=AO12,$G12=AP12),"0",if(($F12-$G12)*(AO12-AP12)>0,0.5*'Thể lệ'!$E$6,'Thể lệ'!$E$6))) -> 5000 | CV12: =if($F12=$G12,if(and($F12=$G12,AQ12<>AR12),'Thể lệ'!$E$6,if($F12=AQ12,0,0.5*'Thể lệ'!$E$6)),if(and($F12=AQ12,$G12=AR12),"0",if(($F12-$G12)*(AQ12-AR12)>0,0.5*'Thể lệ'!$E$6,'Thể lệ'!$E$6))) -> 10000 | CX12: =if($F12=$G12,if(and($F12=$G12,AS12<>AT12),'Thể lệ'!$E$6,if($F12=AS12,0,0.5*'Thể lệ'!$E$6)),if(and($F12=AS12,$G12=AT12),"0",if(($F12-$G12)*(AS12-AT12)>0,0.5*'Thể lệ'!$E$6,'Thể lệ'!$E$6))) -> 10000 | CZ12: =if($F12=$G12,if(and($F12=$G12,AU12<>AV12),'Thể lệ'!$E$6,if($F12=AU12,0,0.5*'Thể lệ'!$E$6)),if(and($F12=AU12,$G12=AV12),"0",if(($F12-$G12)*(AU12-AV12)>0,0.5*'Thể lệ'!$E$6,'Thể lệ'!$E$6))) -> 10000 | DB12: =if($F12=$G12,if(and($F12=$G12,AW12<>AX12),'Thể lệ'!$E$6,if($F12=AW12,0,0.5*'Thể lệ'!$E$6)),if(and($F12=AW12,$G12=AX12),"0",if(($F12-$G12)*(AW12-AX12)>0,0.5*'Thể lệ'!$E$6,'Thể lệ'!$E$6))) -> 0 | DD12: =if($F12=$G12,if(and($F12=$G12,AY12<>AZ12),'Thể lệ'!$E$6,if($F12=AY12,0,0.5*'Thể lệ'!$E$6)),if(and($F12=AY12,$G12=AZ12),"0",if(($F12-$G12)*(AY12-AZ12)>0,0.5*'Thể lệ'!$E$6,'Thể lệ'!$E$6))) -> 10000 | DF12: =if($F12=$G12,if(and($F12=$G12,BA12<>BB12),'Thể lệ'!$E$6,if($F12=BA12,0,0.5*'Thể lệ'!$E$6)),if(and($F12=BA12,$G12=BB12),"0",if(($F12-$G12)*(BA12-BB12)>0,0.5*'Thể lệ'!$E$6,'Thể lệ'!$E$6))) -> 10000 | DH12: =if($F12=$G12,if(and($F12=$G12,BC12<>BD12),'Thể lệ'!$E$6,if($F12=BC12,0,0.5*'Thể lệ'!$E$6)),if(and($F12=BC12,$G12=BD12),"0",if(($F12-$G12)*(BC12-BD12)>0,0.5*'Thể lệ'!$E$6,'Thể lệ'!$E$6))) -> 10000 | DJ12: =if($F12=$G12,if(and($F12=$G12,BE12<>BF12),'Thể lệ'!$E$6,if($F12=BE12,0,0.5*'Thể lệ'!$E$6)),if(and($F12=BE12,$G12=BF12),"0",if(($F12-$G12)*(BE12-BF12)>0,0.5*'Thể lệ'!$E$6,'Thể lệ'!$E$6))) -> 10000 | DL12: =if($F12=$G12,if(and($F12=$G12,BG12<>BH12),'Thể lệ'!$E$6,if($F12=BG12,0,0.5*'Thể lệ'!$E$6)),if(and($F12=BG12,$G12=BH12),"0",if(($F12-$G12)*(BG12-BH12)>0,0.5*'Thể lệ'!$E$6,'Thể lệ'!$E$6))) -> 0 | DN12: =if($F12=$G12,if(and($F12=$G12,BI12<>BJ12),'Thể lệ'!$E$6,if($F12=BI12,0,0.5*'Thể lệ'!$E$6)),if(and($F12=BI12,$G12=BJ12),"0",if(($F12-$G12)*(BI12-BJ12)>0,0.5*'Thể lệ'!$E$6,'Thể lệ'!$E$6))) -> 10000
B13: 7 | C13: 46187.333 | D13: 46187.333 | E13: Haiti | H13: Scotland | K13: 1 | L13: 2 | O13: 0 | P13: 2 | Q13: =AE13 -> 1 | R13: =AF13 -> 2 | S13: 0 | T13: 2 | U13: 0 | V13: 1 | W13: 0 | X13: 1 | Y13: 1 | Z13: 2 | AE13: 1 | AF13: 2 | AK13: 0 | AL13: 1 | AO13: 2 | AP13: 3 | AQ13: =BE13 -> 1 | AR13: =BF13 -> 2 | AS13: 1 | AT13: 1 | AY13: 0 | AZ13: 2 | BA13: 1 | BB13: 2 | BC13: 0 | BD13: 2 | BE13: 1 | BF13: 2 | BI13: =H.Son!H13 -> 0 | BJ13: =H.Son!I13 -> 2 | BN13: =if($F13=$G13,if(and($F13=$G13,I13<>J13),'Thể lệ'!$E$6,if($F13=I13,0,0.5*'Thể lệ'!$E$6)),if(and($F13=I13,$G13=J13),"0",if(($F13-$G13)*(I13-J13)>0,0.5*'Thể lệ'!$E$6,'Thể lệ'!$E$6))) -> 0 | BP13: =if($F13=$G13,if(and($F13=$G13,K13<>L13),'Thể lệ'!$E$6,if($F13=K13,0,0.5*'Thể lệ'!$E$6)),if(and($F13=K13,$G13=L13),"0",if(($F13-$G13)*(K13-L13)>0,0.5*'Thể lệ'!$E$6,'Thể lệ'!$E$6))) -> 10000 | BR13: =if($F13=$G13,if(and($F13=$G13,M13<>N13),'Thể lệ'!$E$6,if($F13=M13,0,0.5*'Thể lệ'!$E$6)),if(and($F13=M13,$G13=N13),"0",if(($F13-$G13)*(M13-N13)>0,0.5*'Thể lệ'!$E$6,'Thể lệ'!$E$6))) -> 0 | BT13: =if($F13=$G13,if(and($F13=$G13,O13<>P13),'Thể lệ'!$E$6,if($F13=O13,0,0.5*'Thể lệ'!$E$6)),if(and($F13=O13,$G13=P13),"0",if(($F13-$G13)*(O13-P13)>0,0.5*'Thể lệ'!$E$6,'Thể lệ'!$E$6))) -> 10000 | BV13: =if($F13=$G13,if(and($F13=$G13,Q13<>R13),'Thể lệ'!$E$6,if($F13=Q13,0,0.5*'Thể lệ'!$E$6)),if(and($F13=Q13,$G13=R13),"0",if(($F13-$G13)*(Q13-R13)>0,0.5*'Thể lệ'!$E$6,'Thể lệ'!$E$6))) -> 10000 | BX13: =if($F13=$G13,if(and($F13=$G13,S13<>T13),'Thể lệ'!$E$6,if($F13=S13,0,0.5*'Thể lệ'!$E$6)),if(and($F13=S13,$G13=T13),"0",if(($F13-$G13)*(S13-T13)>0,0.5*'Thể lệ'!$E$6,'Thể lệ'!$E$6))) -> 10000 | BZ13: =if($F13=$G13,if(and($F13=$G13,U13<>V13),'Thể lệ'!$E$6,if($F13=U13,0,0.5*'Thể lệ'!$E$6)),if(and($F13=U13,$G13=V13),"0",if(($F13-$G13)*(U13-V13)>0,0.5*'Thể lệ'!$E$6,'Thể lệ'!$E$6))) -> 10000 | CB13: =if($F13=$G13,if(and($F13=$G13,W13<>X13),'Thể lệ'!$E$6,if($F13=W13,0,0.5*'Thể lệ'!$E$6)),if(and($F13=W13,$G13=X13),"0",if(($F13-$G13)*(W13-X13)>0,0.5*'Thể lệ'!$E$6,'Thể lệ'!$E$6))) -> 10000 | CD13: =if($F13=$G13,if(and($F13=$G13,Y13<>Z13),'Thể lệ'!$E$6,if($F13=Y13,0,0.5*'Thể lệ'!$E$6)),if(and($F13=Y13,$G13=Z13),"0",if(($F13-$G13)*(Y13-Z13)>0,0.5*'Thể lệ'!$E$6,'Thể lệ'!$E$6))) -> 10000 | CF13: =if($F13=$G13,if(and($F13=$G13,AA13<>AB13),'Thể lệ'!$E$6,if($F13=AA13,0,0.5*'Thể lệ'!$E$6)),if(and($F13=AA13,$G13=AB13),"0",if(($F13-$G13)*(AA13-AB13)>0,0.5*'Thể lệ'!$E$6,'Thể lệ'!$E$6))) -> 0 | CH13: =if($F13=$G13,if(and($F13=$G13,AC13<>AD13),'Thể lệ'!$E$6,if($F13=AC13,0,0.5*'Thể lệ'!$E$6)),if(and($F13=AC13,$G13=AD13),"0",if(($F13-$G13)*(AC13-AD13)>0,0.5*'Thể lệ'!$E$6,'Thể lệ'!$E$6))) -> 0 | CJ13: =if($F13=$G13,if(and($F13=$G13,AE13<>AF13),'Thể lệ'!$E$6,if($F13=AE13,0,0.5*'Thể lệ'!$E$6)),if(and($F13=AE13,$G13=AF13),"0",if(($F13-$G13)*(AE13-AF13)>0,0.5*'Thể lệ'!$E$6,'Thể lệ'!$E$6))) -> 10000 | CL13: =if($F13=$G13,if(and($F13=$G13,AG13<>AH13),'Thể lệ'!$E$6,if($F13=AG13,0,0.5*'Thể lệ'!$E$6)),if(and($F13=AG13,$G13=AH13),"0",if(($F13-$G13)*(AG13-AH13)>0,0.5*'Thể lệ'!$E$6,'Thể lệ'!$E$6))) -> 0 | CN13: =if($F13=$G13,if(and($F13=$G13,AI13<>AJ13),'Thể lệ'!$E$6,if($F13=AI13,0,0.5*'Thể lệ'!$E$6)),if(and($F13=AI13,$G13=AJ13),"0",if(($F13-$G13)*(AI13-AJ13)>0,0.5*'Thể lệ'!$E$6,'Thể lệ'!$E$6))) -> 0 | CP13: =if($F13=$G13,if(and($F13=$G13,AK13<>AL13),'Thể lệ'!$E$6,if($F13=AK13,0,0.5*'Thể lệ'!$E$6)),if(and($F13=AK13,$G13=AL13),"0",if(($F13-$G13)*(AK13-AL13)>0,0.5*'Thể lệ'!$E$6,'Thể lệ'!$E$6))) -> 10000 | CR13: =if($F13=$G13,if(and($F13=$G13,AM13<>AN13),'Thể lệ'!$E$6,if($F13=AM13,0,0.5*'Thể lệ'!$E$6)),if(and($F13=AM13,$G13=AN13),"0",if(($F13-$G13)*(AM13-AN13)>0,0.5*'Thể lệ'!$E$6,'Thể lệ'!$E$6))) -> 0 | CT13: =if($F13=$G13,if(and($F13=$G13,AO13<>AP13),'Thể lệ'!$E$6,if($F13=AO13,0,0.5*'Thể lệ'!$E$6)),if(and($F13=AO13,$G13=AP13),"0",if(($F13-$G13)*(AO13-AP13)>0,0.5*'Thể lệ'!$E$6,'Thể lệ'!$E$6))) -> 10000 | CV13: =if($F13=$G13,if(and($F13=$G13,AQ13<>AR13),'Thể lệ'!$E$6,if($F13=AQ13,0,0.5*'Thể lệ'!$E$6)),if(and($F13=AQ13,$G13=AR13),"0",if(($F13-$G13)*(AQ13-AR13)>0,0.5*'Thể lệ'!$E$6,'Thể lệ'!$E$6))) -> 10000 | CX13: =if($F13=$G13,if(and($F13=$G13,AS13<>AT13),'Thể lệ'!$E$6,if($F13=AS13,0,0.5*'Thể lệ'!$E$6)),if(and($F13=AS13,$G13=AT13),"0",if(($F13-$G13)*(AS13-AT13)>0,0.5*'Thể lệ'!$E$6,'Thể lệ'!$E$6))) -> 5000 | CZ13: =if($F13=$G13,if(and($F13=$G13,AU13<>AV13),'Thể lệ'!$E$6,if($F13=AU13,0,0.5*'Thể lệ'!$E$6)),if(and($F13=AU13,$G13=AV13),"0",if(($F13-$G13)*(AU13-AV13)>0,0.5*'Thể lệ'!$E$6,'Thể lệ'!$E$6))) -> 0 | DB13: =if($F13=$G13,if(and($F13=$G13,AW13<>AX13),'Thể lệ'!$E$6,if($F13=AW13,0,0.5*'Thể lệ'!$E$6)),if(and($F13=AW13,$G13=AX13),"0",if(($F13-$G13)*(AW13-AX13)>0,0.5*'Thể lệ'!$E$6,'Thể lệ'!$E$6))) -> 0 | DD13: =if($F13=$G13,if(and($F13=$G13,AY13<>AZ13),'Thể lệ'!$E$6,if($F13=AY13,0,0.5*'Thể lệ'!$E$6)),if(and($F13=AY13,$G13=AZ13),"0",if(($F13-$G13)*(AY13-AZ13)>0,0.5*'Thể lệ'!$E$6,'Thể lệ'!$E$6))) -> 10000 | DF13: =if($F13=$G13,if(and($F13=$G13,BA13<>BB13),'Thể lệ'!$E$6,if($F13=BA13,0,0.5*'Thể lệ'!$E$6)),if(and($F13=BA13,$G13=BB13),"0",if(($F13-$G13)*(BA13-BB13)>0,0.5*'Thể lệ'!$E$6,'Thể lệ'!$E$6))) -> 10000 | DH13: =if($F13=$G13,if(and($F13=$G13,BC13<>BD13),'Thể lệ'!$E$6,if($F13=BC13,0,0.5*'Thể lệ'!$E$6)),if(and($F13=BC13,$G13=BD13),"0",if(($F13-$G13)*(BC13-BD13)>0,0.5*'Thể lệ'!$E$6,'Thể lệ'!$E$6))) -> 10000 | DJ13: =if($F13=$G13,if(and($F13=$G13,BE13<>BF13),'Thể lệ'!$E$6,if($F13=BE13,0,0.5*'Thể lệ'!$E$6)),if(and($F13=BE13,$G13=BF13),"0",if(($F13-$G13)*(BE13-BF13)>0,0.5*'Thể lệ'!$E$6,'Thể lệ'!$E$6))) -> 10000 | DL13: =if($F13=$G13,if(and($F13=$G13,BG13<>BH13),'Thể lệ'!$E$6,if($F13=BG13,0,0.5*'Thể lệ'!$E$6)),if(and($F13=BG13,$G13=BH13),"0",if(($F13-$G13)*(BG13-BH13)>0,0.5*'Thể lệ'!$E$6,'Thể lệ'!$E$6))) -> 0 | DN13: =if($F13=$G13,if(and($F13=$G13,BI13<>BJ13),'Thể lệ'!$E$6,if($F13=BI13,0,0.5*'Thể lệ'!$E$6)),if(and($F13=BI13,$G13=BJ13),"0",if(($F13-$G13)*(BI13-BJ13)>0,0.5*'Thể lệ'!$E$6,'Thể lệ'!$E$6))) -> 10000
B14: 8 | C14: 46187.458 | D14: 46187.458 | E14: Australia | H14: Turkey | K14: 2 | L14: 2 | O14: 1 | P14: 1 | Q14: =AE14 -> 0 | R14: =AF14 -> 2 | S14: 1 | T14: 1 | U14: 1 | V14: 2 | W14: 1 | X14: 2 | Y14: 1 | Z14: 2 | AE14: 0 | AF14: 2 | AK14: 0 | AL14: 0 | AO14: 2 | AP14: 2 | AQ14: =BE14 -> 1 | AR14: =BF14 -> 2 | AS14: 1 | AT14: 1 | AY14: 1 | AZ14: 2 | BA14: 1 | BB14: 1 | BC14: 1 | BD14: 2 | BE14: 1 | BF14: 2 | BI14: =H.Son!H14 -> 1 | BJ14: =H.Son!I14 -> 1 | BN14: =if($F14=$G14,if(and($F14=$G14,I14<>J14),'Thể lệ'!$E$6,if($F14=I14,0,0.5*'Thể lệ'!$E$6)),if(and($F14=I14,$G14=J14),"0",if(($F14-$G14)*(I14-J14)>0,0.5*'Thể lệ'!$E$6,'Thể lệ'!$E$6))) -> 0 | BP14: =if($F14=$G14,if(and($F14=$G14,K14<>L14),'Thể lệ'!$E$6,if($F14=K14,0,0.5*'Thể lệ'!$E$6)),if(and($F14=K14,$G14=L14),"0",if(($F14-$G14)*(K14-L14)>0,0.5*'Thể lệ'!$E$6,'Thể lệ'!$E$6))) -> 5000 | BR14: =if($F14=$G14,if(and($F14=$G14,M14<>N14),'Thể lệ'!$E$6,if($F14=M14,0,0.5*'Thể lệ'!$E$6)),if(and($F14=M14,$G14=N14),"0",if(($F14-$G14)*(M14-N14)>0,0.5*'Thể lệ'!$E$6,'Thể lệ'!$E$6))) -> 0 | BT14: =if($F14=$G14,if(and($F14=$G14,O14<>P14),'Thể lệ'!$E$6,if($F14=O14,0,0.5*'Thể lệ'!$E$6)),if(and($F14=O14,$G14=P14),"0",if(($F14-$G14)*(O14-P14)>0,0.5*'Thể lệ'!$E$6,'Thể lệ'!$E$6))) -> 5000 | BV14: =if($F14=$G14,if(and($F14=$G14,Q14<>R14),'Thể lệ'!$E$6,if($F14=Q14,0,0.5*'Thể lệ'!$E$6)),if(and($F14=Q14,$G14=R14),"0",if(($F14-$G14)*(Q14-R14)>0,0.5*'Thể lệ'!$E$6,'Thể lệ'!$E$6))) -> 10000 | BX14: =if($F14=$G14,if(and($F14=$G14,S14<>T14),'Thể lệ'!$E$6,if($F14=S14,0,0.5*'Thể lệ'!$E$6)),if(and($F14=S14,$G14=T14),"0",if(($F14-$G14)*(S14-T14)>0,0.5*'Thể lệ'!$E$6,'Thể lệ'!$E$6))) -> 5000 | BZ14: =if($F14=$G14,if(and($F14=$G14,U14<>V14),'Thể lệ'!$E$6,if($F14=U14,0,0.5*'Thể lệ'!$E$6)),if(and($F14=U14,$G14=V14),"0",if(($F14-$G14)*(U14-V14)>0,0.5*'Thể lệ'!$E$6,'Thể lệ'!$E$6))) -> 10000 | CB14: =if($F14=$G14,if(and($F14=$G14,W14<>X14),'Thể lệ'!$E$6,if($F14=W14,0,0.5*'Thể lệ'!$E$6)),if(and($F14=W14,$G14=X14),"0",if(($F14-$G14)*(W14-X14)>0,0.5*'Thể lệ'!$E$6,'Thể lệ'!$E$6))) -> 10000 | CD14: =if($F14=$G14,if(and($F14=$G14,Y14<>Z14),'Thể lệ'!$E$6,if($F14=Y14,0,0.5*'Thể lệ'!$E$6)),if(and($F14=Y14,$G14=Z14),"0",if(($F14-$G14)*(Y14-Z14)>0,0.5*'Thể lệ'!$E$6,'Thể lệ'!$E$6))) -> 10000 | CF14: =if($F14=$G14,if(and($F14=$G14,AA14<>AB14),'Thể lệ'!$E$6,if($F14=AA14,0,0.5*'Thể lệ'!$E$6)),if(and($F14=AA14,$G14=AB14),"0",if(($F14-$G14)*(AA14-AB14)>0,0.5*'Thể lệ'!$E$6,'Thể lệ'!$E$6))) -> 0 | CH14: =if($F14=$G14,if(and($F14=$G14,AC14<>AD14),'Thể lệ'!$E$6,if($F14=AC14,0,0.5*'Thể lệ'!$E$6)),if(and($F14=AC14,$G14=AD14),"0",if(($F14-$G14)*(AC14-AD14)>0,0.5*'Thể lệ'!$E$6,'Thể lệ'!$E$6))) -> 0 | CJ14: =if($F14=$G14,if(and($F14=$G14,AE14<>AF14),'Thể lệ'!$E$6,if($F14=AE14,0,0.5*'Thể lệ'!$E$6)),if(and($F14=AE14,$G14=AF14),"0",if(($F14-$G14)*(AE14-AF14)>0,0.5*'Thể lệ'!$E$6,'Thể lệ'!$E$6))) -> 10000 | CL14: =if($F14=$G14,if(and($F14=$G14,AG14<>AH14),'Thể lệ'!$E$6,if($F14=AG14,0,0.5*'Thể lệ'!$E$6)),if(and($F14=AG14,$G14=AH14),"0",if(($F14-$G14)*(AG14-AH14)>0,0.5*'Thể lệ'!$E$6,'Thể lệ'!$E$6))) -> 0 | CN14: =if($F14=$G14,if(and($F14=$G14,AI14<>AJ14),'Thể lệ'!$E$6,if($F14=AI14,0,0.5*'Thể lệ'!$E$6)),if(and($F14=AI14,$G14=AJ14),"0",if(($F14-$G14)*(AI14-AJ14)>0,0.5*'Thể lệ'!$E$6,'Thể lệ'!$E$6))) -> 0 | CP14: =if($F14=$G14,if(and($F14=$G14,AK14<>AL14),'Thể lệ'!$E$6,if($F14=AK14,0,0.5*'Thể lệ'!$E$6)),if(and($F14=AK14,$G14=AL14),"0",if(($F14-$G14)*(AK14-AL14)>0,0.5*'Thể lệ'!$E$6,'Thể lệ'!$E$6))) -> 0 | CR14: =if($F14=$G14,if(and($F14=$G14,AM14<>AN14),'Thể lệ'!$E$6,if($F14=AM14,0,0.5*'Thể lệ'!$E$6)),if(and($F14=AM14,$G14=AN14),"0",if(($F14-$G14)*(AM14-AN14)>0,0.5*'Thể lệ'!$E$6,'Thể lệ'!$E$6))) -> 0 | CT14: =if($F14=$G14,if(and($F14=$G14,AO14<>AP14),'Thể lệ'!$E$6,if($F14=AO14,0,0.5*'Thể lệ'!$E$6)),if(and($F14=AO14,$G14=AP14),"0",if(($F14-$G14)*(AO14-AP14)>0,0.5*'Thể lệ'!$E$6,'Thể lệ'!$E$6))) -> 5000 | CV14: =if($F14=$G14,if(and($F14=$G14,AQ14<>AR14),'Thể lệ'!$E$6,if($F14=AQ14,0,0.5*'Thể lệ'!$E$6)),if(and($F14=AQ14,$G14=AR14),"0",if(($F14-$G14)*(AQ14-AR14)>0,0.5*'Thể lệ'!$E$6,'Thể lệ'!$E$6))) -> 10000 | CX14: =if($F14=$G14,if(and($F14=$G14,AS14<>AT14),'Thể lệ'!$E$6,if($F14=AS14,0,0.5*'Thể lệ'!$E$6)),if(and($F14=AS14,$G14=AT14),"0",if(($F14-$G14)*(AS14-AT14)>0,0.5*'Thể lệ'!$E$6,'Thể lệ'!$E$6))) -> 5000 | CZ14: =if($F14=$G14,if(and($F14=$G14,AU14<>AV14),'Thể lệ'!$E$6,if($F14=AU14,0,0.5*'Thể lệ'!$E$6)),if(and($F14=AU14,$G14=AV14),"0",if(($F14-$G14)*(AU14-AV14)>0,0.5*'Thể lệ'!$E$6,'Thể lệ'!$E$6))) -> 0 | DB14: =if($F14=$G14,if(and($F14=$G14,AW14<>AX14),'Thể lệ'!$E$6,if($F14=AW14,0,0.5*'Thể lệ'!$E$6)),if(and($F14=AW14,$G14=AX14),"0",if(($F14-$G14)*(AW14-AX14)>0,0.5*'Thể lệ'!$E$6,'Thể lệ'!$E$6))) -> 0 | DD14: =if($F14=$G14,if(and($F14=$G14,AY14<>AZ14),'Thể lệ'!$E$6,if($F14=AY14,0,0.5*'Thể lệ'!$E$6)),if(and($F14=AY14,$G14=AZ14),"0",if(($F14-$G14)*(AY14-AZ14)>0,0.5*'Thể lệ'!$E$6,'Thể lệ'!$E$6))) -> 10000 | DF14: =if($F14=$G14,if(and($F14=$G14,BA14<>BB14),'Thể lệ'!$E$6,if($F14=BA14,0,0.5*'Thể lệ'!$E$6)),if(and($F14=BA14,$G14=BB14),"0",if(($F14-$G14)*(BA14-BB14)>0,0.5*'Thể lệ'!$E$6,'Thể lệ'!$E$6))) -> 5000 | DH14: =if($F14=$G14,if(and($F14=$G14,BC14<>BD14),'Thể lệ'!$E$6,if($F14=BC14,0,0.5*'Thể lệ'!$E$6)),if(and($F14=BC14,$G14=BD14),"0",if(($F14-$G14)*(BC14-BD14)>0,0.5*'Thể lệ'!$E$6,'Thể lệ'!$E$6))) -> 10000 | DJ14: =if($F14=$G14,if(and($F14=$G14,BE14<>BF14),'Thể lệ'!$E$6,if($F14=BE14,0,0.5*'Thể lệ'!$E$6)),if(and($F14=BE14,$G14=BF14),"0",if(($F14-$G14)*(BE14-BF14)>0,0.5*'Thể lệ'!$E$6,'Thể lệ'!$E$6))) -> 10000 | DL14: =if($F14=$G14,if(and($F14=$G14,BG14<>BH14),'Thể lệ'!$E$6,if($F14=BG14,0,0.5*'Thể lệ'!$E$6)),if(and($F14=BG14,$G14=BH14),"0",if(($F14-$G14)*(BG14-BH14)>0,0.5*'Thể lệ'!$E$6,'Thể lệ'!$E$6))) -> 0 | DN14: =if($F14=$G14,if(and($F14=$G14,BI14<>BJ14),'Thể lệ'!$E$6,if($F14=BI14,0,0.5*'Thể lệ'!$E$6)),if(and($F14=BI14,$G14=BJ14),"0",if(($F14-$G14)*(BI14-BJ14)>0,0.5*'Thể lệ'!$E$6,'Thể lệ'!$E$6))) -> 5000
B15: 9 | C15: 46188 | D15: 46188 | E15: Germany | H15: Curaçao | K15: 3 | L15: 0 | O15: 4 | P15: 0 | Q15: =AE15 -> 2 | R15: =AF15 -> 0 | S15: 4 | T15: 0 | U15: 2 | V15: 0 | W15: 2 | X15: 0 | Y15: 3 | Z15: 0 | AE15: 2 | AF15: 0 | AK15: 2 | AL15: 0 | AO15: 2 | AP15: 0 | AQ15: =BE15 -> 2 | AR15: =BF15 -> 0 | AS15: 3 | AT15: 0 | BA15: 3 | BB15: 0 | BC15: 5 | BD15: 0 | BE15: 2 | BF15: 0 | BI15: =H.Son!H15 -> 4 | BJ15: =H.Son!I15 -> 0 | BN15: =if($F15=$G15,if(and($F15=$G15,I15<>J15),'Thể lệ'!$E$6,if($F15=I15,0,0.5*'Thể lệ'!$E$6)),if(and($F15=I15,$G15=J15),"0",if(($F15-$G15)*(I15-J15)>0,0.5*'Thể lệ'!$E$6,'Thể lệ'!$E$6))) -> 0 | BP15: =if($F15=$G15,if(and($F15=$G15,K15<>L15),'Thể lệ'!$E$6,if($F15=K15,0,0.5*'Thể lệ'!$E$6)),if(and($F15=K15,$G15=L15),"0",if(($F15-$G15)*(K15-L15)>0,0.5*'Thể lệ'!$E$6,'Thể lệ'!$E$6))) -> 10000 | BR15: =if($F15=$G15,if(and($F15=$G15,M15<>N15),'Thể lệ'!$E$6,if($F15=M15,0,0.5*'Thể lệ'!$E$6)),if(and($F15=M15,$G15=N15),"0",if(($F15-$G15)*(M15-N15)>0,0.5*'Thể lệ'!$E$6,'Thể lệ'!$E$6))) -> 0 | BT15: =if($F15=$G15,if(and($F15=$G15,O15<>P15),'Thể lệ'!$E$6,if($F15=O15,0,0.5*'Thể lệ'!$E$6)),if(and($F15=O15,$G15=P15),"0",if(($F15-$G15)*(O15-P15)>0,0.5*'Thể lệ'!$E$6,'Thể lệ'!$E$6))) -> 10000 | BV15: =if($F15=$G15,if(and($F15=$G15,Q15<>R15),'Thể lệ'!$E$6,if($F15=Q15,0,0.5*'Thể lệ'!$E$6)),if(and($F15=Q15,$G15=R15),"0",if(($F15-$G15)*(Q15-R15)>0,0.5*'Thể lệ'!$E$6,'Thể lệ'!$E$6))) -> 10000 | BX15: =if($F15=$G15,if(and($F15=$G15,S15<>T15),'Thể lệ'!$E$6,if($F15=S15,0,0.5*'Thể lệ'!$E$6)),if(and($F15=S15,$G15=T15),"0",if(($F15-$G15)*(S15-T15)>0,0.5*'Thể lệ'!$E$6,'Thể lệ'!$E$6))) -> 10000 | BZ15: =if($F15=$G15,if(and($F15=$G15,U15<>V15),'Thể lệ'!$E$6,if($F15=U15,0,0.5*'Thể lệ'!$E$6)),if(and($F15=U15,$G15=V15),"0",if(($F15-$G15)*(U15-V15)>0,0.5*'Thể lệ'!$E$6,'Thể lệ'!$E$6))) -> 10000 | CB15: =if($F15=$G15,if(and($F15=$G15,W15<>X15),'Thể lệ'!$E$6,if($F15=W15,0,0.5*'Thể lệ'!$E$6)),if(and($F15=W15,$G15=X15),"0",if(($F15-$G15)*(W15-X15)>0,0.5*'Thể lệ'!$E$6,'Thể lệ'!$E$6))) -> 10000 | CD15: =if($F15=$G15,if(and($F15=$G15,Y15<>Z15),'Thể lệ'!$E$6,if($F15=Y15,0,0.5*'Thể lệ'!$E$6)),if(and($F15=Y15,$G15=Z15),"0",if(($F15-$G15)*(Y15-Z15)>0,0.5*'Thể lệ'!$E$6,'Thể lệ'!$E$6))) -> 10000 | CF15: =if($F15=$G15,if(and($F15=$G15,AA15<>AB15),'Thể lệ'!$E$6,if($F15=AA15,0,0.5*'Thể lệ'!$E$6)),if(and($F15=AA15,$G15=AB15),"0",if(($F15-$G15)*(AA15-AB15)>0,0.5*'Thể lệ'!$E$6,'Thể lệ'!$E$6))) -> 0 | CH15: =if($F15=$G15,if(and($F15=$G15,AC15<>AD15),'Thể lệ'!$E$6,if($F15=AC15,0,0.5*'Thể lệ'!$E$6)),if(and($F15=AC15,$G15=AD15),"0",if(($F15-$G15)*(AC15-AD15)>0,0.5*'Thể lệ'!$E$6,'Thể lệ'!$E$6))) -> 0 | CJ15: =if($F15=$G15,if(and($F15=$G15,AE15<>AF15),'Thể lệ'!$E$6,if($F15=AE15,0,0.5*'Thể lệ'!$E$6)),if(and($F15=AE15,$G15=AF15),"0",if(($F15-$G15)*(AE15-AF15)>0,0.5*'Thể lệ'!$E$6,'Thể lệ'!$E$6))) -> 10000 | CL15: =if($F15=$G15,if(and($F15=$G15,AG15<>AH15),'Thể lệ'!$E$6,if($F15=AG15,0,0.5*'Thể lệ'!$E$6)),if(and($F15=AG15,$G15=AH15),"0",if(($F15-$G15)*(AG15-AH15)>0,0.5*'Thể lệ'!$E$6,'Thể lệ'!$E$6))) -> 0 | CN15: =if($F15=$G15,if(and($F15=$G15,AI15<>AJ15),'Thể lệ'!$E$6,if($F15=AI15,0,0.5*'Thể lệ'!$E$6)),if(and($F15=AI15,$G15=AJ15),"0",if(($F15-$G15)*(AI15-AJ15)>0,0.5*'Thể lệ'!$E$6,'Thể lệ'!$E$6))) -> 0 | CP15: =if($F15=$G15,if(and($F15=$G15,AK15<>AL15),'Thể lệ'!$E$6,if($F15=AK15,0,0.5*'Thể lệ'!$E$6)),if(and($F15=AK15,$G15=AL15),"0",if(($F15-$G15)*(AK15-AL15)>0,0.5*'Thể lệ'!$E$6,'Thể lệ'!$E$6))) -> 10000 | CR15: =if($F15=$G15,if(and($F15=$G15,AM15<>AN15),'Thể lệ'!$E$6,if($F15=AM15,0,0.5*'Thể lệ'!$E$6)),if(and($F15=AM15,$G15=AN15),"0",if(($F15-$G15)*(AM15-AN15)>0,0.5*'Thể lệ'!$E$6,'Thể lệ'!$E$6))) -> 0 | CT15: =if($F15=$G15,if(and($F15=$G15,AO15<>AP15),'Thể lệ'!$E$6,if($F15=AO15,0,0.5*'Thể lệ'!$E$6)),if(and($F15=AO15,$G15=AP15),"0",if(($F15-$G15)*(AO15-AP15)>0,0.5*'Thể lệ'!$E$6,'Thể lệ'!$E$6))) -> 10000 | CV15: =if($F15=$G15,if(and($F15=$G15,AQ15<>AR15),'Thể lệ'!$E$6,if($F15=AQ15,0,0.5*'Thể lệ'!$E$6)),if(and($F15=AQ15,$G15=AR15),"0",if(($F15-$G15)*(AQ15-AR15)>0,0.5*'Thể lệ'!$E$6,'Thể lệ'!$E$6))) -> 10000 | CX15: =if($F15=$G15,if(and($F15=$G15,AS15<>AT15),'Thể lệ'!$E$6,if($F15=AS15,0,0.5*'Thể lệ'!$E$6)),if(and($F15=AS15,$G15=AT15),"0",if(($F15-$G15)*(AS15-AT15)>0,0.5*'Thể lệ'!$E$6,'Thể lệ'!$E$6))) -> 10000 | CZ15: =if($F15=$G15,if(and($F15=$G15,AU15<>AV15),'Thể lệ'!$E$6,if($F15=AU15,0,0.5*'Thể lệ'!$E$6)),if(and($F15=AU15,$G15=AV15),"0",if(($F15-$G15)*(AU15-AV15)>0,0.5*'Thể lệ'!$E$6,'Thể lệ'!$E$6))) -> 0 | DB15: =if($F15=$G15,if(and($F15=$G15,AW15<>AX15),'Thể lệ'!$E$6,if($F15=AW15,0,0.5*'Thể lệ'!$E$6)),if(and($F15=AW15,$G15=AX15),"0",if(($F15-$G15)*(AW15-AX15)>0,0.5*'Thể lệ'!$E$6,'Thể lệ'!$E$6))) -> 0 | DD15: =if($F15=$G15,if(and($F15=$G15,AY15<>AZ15),'Thể lệ'!$E$6,if($F15=AY15,0,0.5*'Thể lệ'!$E$6)),if(and($F15=AY15,$G15=AZ15),"0",if(($F15-$G15)*(AY15-AZ15)>0,0.5*'Thể lệ'!$E$6,'Thể lệ'!$E$6))) -> 0 | DF15: =if($F15=$G15,if(and($F15=$G15,BA15<>BB15),'Thể lệ'!$E$6,if($F15=BA15,0,0.5*'Thể lệ'!$E$6)),if(and($F15=BA15,$G15=BB15),"0",if(($F15-$G15)*(BA15-BB15)>0,0.5*'Thể lệ'!$E$6,'Thể lệ'!$E$6))) -> 10000 | DH15: =if($F15=$G15,if(and($F15=$G15,BC15<>BD15),'Thể lệ'!$E$6,if($F15=BC15,0,0.5*'Thể lệ'!$E$6)),if(and($F15=BC15,$G15=BD15),"0",if(($F15-$G15)*(BC15-BD15)>0,0.5*'Thể lệ'!$E$6,'Thể lệ'!$E$6))) -> 10000 | DJ15: =if($F15=$G15,if(and($F15=$G15,BE15<>BF15),'Thể lệ'!$E$6,if($F15=BE15,0,0.5*'Thể lệ'!$E$6)),if(and($F15=BE15,$G15=BF15),"0",if(($F15-$G15)*(BE15-BF15)>0,0.5*'Thể lệ'!$E$6,'Thể lệ'!$E$6))) -> 10000 | DL15: =if($F15=$G15,if(and($F15=$G15,BG15<>BH15),'Thể lệ'!$E$6,if($F15=BG15,0,0.5*'Thể lệ'!$E$6)),if(and($F15=BG15,$G15=BH15),"0",if(($F15-$G15)*(BG15-BH15)>0,0.5*'Thể lệ'!$E$6,'Thể lệ'!$E$6))) -> 0 | DN15: =if($F15=$G15,if(and($F15=$G15,BI15<>BJ15),'Thể lệ'!$E$6,if($F15=BI15,0,0.5*'Thể lệ'!$E$6)),if(and($F15=BI15,$G15=BJ15),"0",if(($F15-$G15)*(BI15-BJ15)>0,0.5*'Thể lệ'!$E$6,'Thể lệ'!$E$6))) -> 10000
